WARNING 2025-08-11 15:53:06,255 log Not Found: /
WARNING 2025-08-11 15:53:06,255 basehttp "GET / HTTP/1.1" 404 2782
WARNING 2025-08-11 15:53:06,780 log Not Found: /favicon.ico
WARNING 2025-08-11 15:53:06,780 basehttp "GET /favicon.ico HTTP/1.1" 404 2833
WARNING 2025-08-11 15:58:57,539 log Bad Request: /admin_web/login/
WARNING 2025-08-11 15:58:57,539 basehttp "POST /admin_web/login/ HTTP/1.1" 400 58
ERROR 2025-08-11 15:59:33,687 log Internal Server Error: /admin_web/login/
Traceback (most recent call last):
  File "D:\DMS-GOA\vvenv\Lib\site-packages\django\core\handlers\exception.py", line 55, in inner
    response = get_response(request)
               ^^^^^^^^^^^^^^^^^^^^^
  File "D:\DMS-GOA\vvenv\Lib\site-packages\django\core\handlers\base.py", line 197, in _get_response
    response = wrapped_callback(request, *callback_args, **callback_kwargs)
               ^^^^^^^^^^^^^^^^^^^^^^^^^^^^^^^^^^^^^^^^^^^^^^^^^^^^^^^^^^^^
  File "D:\DMS-GOA\vvenv\Lib\site-packages\django\views\decorators\csrf.py", line 65, in _view_wrapper
    return view_func(request, *args, **kwargs)
           ^^^^^^^^^^^^^^^^^^^^^^^^^^^^^^^^^^^
  File "D:\DMS-GOA\vvenv\Lib\site-packages\django\views\generic\base.py", line 105, in view
    return self.dispatch(request, *args, **kwargs)
           ^^^^^^^^^^^^^^^^^^^^^^^^^^^^^^^^^^^^^^^
  File "D:\DMS-GOA\vvenv\Lib\site-packages\rest_framework\views.py", line 515, in dispatch
    response = self.handle_exception(exc)
               ^^^^^^^^^^^^^^^^^^^^^^^^^^
  File "D:\DMS-GOA\vvenv\Lib\site-packages\rest_framework\views.py", line 475, in handle_exception
    self.raise_uncaught_exception(exc)
  File "D:\DMS-GOA\vvenv\Lib\site-packages\rest_framework\views.py", line 486, in raise_uncaught_exception
    raise exc
  File "D:\DMS-GOA\vvenv\Lib\site-packages\rest_framework\views.py", line 512, in dispatch
    response = handler(request, *args, **kwargs)
               ^^^^^^^^^^^^^^^^^^^^^^^^^^^^^^^^^
  File "D:\DMS-GOA\DMS_goa\admin_web\views.py", line 434, in post
    serializer1.is_valid(raise_exception=True)
  File "D:\DMS-GOA\vvenv\Lib\site-packages\rest_framework\serializers.py", line 225, in is_valid
    self._validated_data = self.run_validation(self.initial_data)
                           ^^^^^^^^^^^^^^^^^^^^^^^^^^^^^^^^^^^^^^
  File "D:\DMS-GOA\vvenv\Lib\site-packages\rest_framework\serializers.py", line 447, in run_validation
    value = self.validate(value)
            ^^^^^^^^^^^^^^^^^^^^
  File "D:\DMS-GOA\DMS_goa\admin_web\serializers.py", line 237, in validate
    return super().validate(attrs)
           ^^^^^^^^^^^^^^^^^^^^^^^
  File "D:\DMS-GOA\vvenv\Lib\site-packages\rest_framework_simplejwt\serializers.py", line 75, in validate
    refresh = self.get_token(self.user)
              ^^^^^^^^^^^^^^^^^^^^^^^^^
  File "D:\DMS-GOA\vvenv\Lib\site-packages\rest_framework_simplejwt\serializers.py", line 66, in get_token
    return cls.token_class.for_user(user)  # type: ignore
           ^^^^^^^^^^^^^^^^^^^^^^^^^^^^^^
  File "D:\DMS-GOA\vvenv\Lib\site-packages\rest_framework_simplejwt\tokens.py", line 326, in for_user
    token = super().for_user(user)  # type: ignore
            ^^^^^^^^^^^^^^^^^^^^^^
  File "D:\DMS-GOA\vvenv\Lib\site-packages\rest_framework_simplejwt\tokens.py", line 238, in for_user
    user_id = getattr(user, api_settings.USER_ID_FIELD)
              ^^^^^^^^^^^^^^^^^^^^^^^^^^^^^^^^^^^^^^^^^
AttributeError: 'DMS_User' object has no attribute 'emp_id'. Did you mean: 'grp_id'?
ERROR 2025-08-11 15:59:33,696 basehttp "POST /admin_web/login/ HTTP/1.1" 500 127706
WARNING 2025-08-11 16:01:17,975 log Bad Request: /admin_web/login/
WARNING 2025-08-11 16:01:17,976 basehttp "POST /admin_web/login/ HTTP/1.1" 400 58
ERROR 2025-08-11 16:01:45,969 log Internal Server Error: /admin_web/login/
Traceback (most recent call last):
  File "D:\DMS-GOA\vvenv\Lib\site-packages\django\core\handlers\exception.py", line 55, in inner
    response = get_response(request)
               ^^^^^^^^^^^^^^^^^^^^^
  File "D:\DMS-GOA\vvenv\Lib\site-packages\django\core\handlers\base.py", line 197, in _get_response
    response = wrapped_callback(request, *callback_args, **callback_kwargs)
               ^^^^^^^^^^^^^^^^^^^^^^^^^^^^^^^^^^^^^^^^^^^^^^^^^^^^^^^^^^^^
  File "D:\DMS-GOA\vvenv\Lib\site-packages\django\views\decorators\csrf.py", line 65, in _view_wrapper
    return view_func(request, *args, **kwargs)
           ^^^^^^^^^^^^^^^^^^^^^^^^^^^^^^^^^^^
  File "D:\DMS-GOA\vvenv\Lib\site-packages\django\views\generic\base.py", line 105, in view
    return self.dispatch(request, *args, **kwargs)
           ^^^^^^^^^^^^^^^^^^^^^^^^^^^^^^^^^^^^^^^
  File "D:\DMS-GOA\vvenv\Lib\site-packages\rest_framework\views.py", line 515, in dispatch
    response = self.handle_exception(exc)
               ^^^^^^^^^^^^^^^^^^^^^^^^^^
  File "D:\DMS-GOA\vvenv\Lib\site-packages\rest_framework\views.py", line 475, in handle_exception
    self.raise_uncaught_exception(exc)
  File "D:\DMS-GOA\vvenv\Lib\site-packages\rest_framework\views.py", line 486, in raise_uncaught_exception
    raise exc
  File "D:\DMS-GOA\vvenv\Lib\site-packages\rest_framework\views.py", line 512, in dispatch
    response = handler(request, *args, **kwargs)
               ^^^^^^^^^^^^^^^^^^^^^^^^^^^^^^^^^
  File "D:\DMS-GOA\DMS_goa\admin_web\views.py", line 434, in post
    serializer1.is_valid(raise_exception=True)
  File "D:\DMS-GOA\vvenv\Lib\site-packages\rest_framework\serializers.py", line 225, in is_valid
    self._validated_data = self.run_validation(self.initial_data)
                           ^^^^^^^^^^^^^^^^^^^^^^^^^^^^^^^^^^^^^^
  File "D:\DMS-GOA\vvenv\Lib\site-packages\rest_framework\serializers.py", line 447, in run_validation
    value = self.validate(value)
            ^^^^^^^^^^^^^^^^^^^^
  File "D:\DMS-GOA\DMS_goa\admin_web\serializers.py", line 237, in validate
    return super().validate(attrs)
           ^^^^^^^^^^^^^^^^^^^^^^^
  File "D:\DMS-GOA\vvenv\Lib\site-packages\rest_framework_simplejwt\serializers.py", line 75, in validate
    refresh = self.get_token(self.user)
              ^^^^^^^^^^^^^^^^^^^^^^^^^
  File "D:\DMS-GOA\vvenv\Lib\site-packages\rest_framework_simplejwt\serializers.py", line 66, in get_token
    return cls.token_class.for_user(user)  # type: ignore
           ^^^^^^^^^^^^^^^^^^^^^^^^^^^^^^
  File "D:\DMS-GOA\vvenv\Lib\site-packages\rest_framework_simplejwt\tokens.py", line 326, in for_user
    token = super().for_user(user)  # type: ignore
            ^^^^^^^^^^^^^^^^^^^^^^
  File "D:\DMS-GOA\vvenv\Lib\site-packages\rest_framework_simplejwt\tokens.py", line 238, in for_user
    user_id = getattr(user, api_settings.USER_ID_FIELD)
              ^^^^^^^^^^^^^^^^^^^^^^^^^^^^^^^^^^^^^^^^^
AttributeError: 'DMS_User' object has no attribute 'emp_id'. Did you mean: 'grp_id'?
ERROR 2025-08-11 16:01:45,994 basehttp "POST /admin_web/login/ HTTP/1.1" 500 127707
WARNING 2025-08-11 16:12:12,040 log Bad Request: /admin_web/login/
WARNING 2025-08-11 16:12:12,041 basehttp "POST /admin_web/login/ HTTP/1.1" 400 58
ERROR 2025-08-11 16:17:38,876 log Internal Server Error: /admin_web/login/
Traceback (most recent call last):
  File "D:\DMS-GOA\vvenv\Lib\site-packages\django\core\handlers\exception.py", line 55, in inner
    response = get_response(request)
               ^^^^^^^^^^^^^^^^^^^^^
  File "D:\DMS-GOA\vvenv\Lib\site-packages\django\core\handlers\base.py", line 197, in _get_response
    response = wrapped_callback(request, *callback_args, **callback_kwargs)
               ^^^^^^^^^^^^^^^^^^^^^^^^^^^^^^^^^^^^^^^^^^^^^^^^^^^^^^^^^^^^
  File "D:\DMS-GOA\vvenv\Lib\site-packages\django\views\decorators\csrf.py", line 65, in _view_wrapper
    return view_func(request, *args, **kwargs)
           ^^^^^^^^^^^^^^^^^^^^^^^^^^^^^^^^^^^
  File "D:\DMS-GOA\vvenv\Lib\site-packages\django\views\generic\base.py", line 105, in view
    return self.dispatch(request, *args, **kwargs)
           ^^^^^^^^^^^^^^^^^^^^^^^^^^^^^^^^^^^^^^^
  File "D:\DMS-GOA\vvenv\Lib\site-packages\rest_framework\views.py", line 515, in dispatch
    response = self.handle_exception(exc)
               ^^^^^^^^^^^^^^^^^^^^^^^^^^
  File "D:\DMS-GOA\vvenv\Lib\site-packages\rest_framework\views.py", line 475, in handle_exception
    self.raise_uncaught_exception(exc)
  File "D:\DMS-GOA\vvenv\Lib\site-packages\rest_framework\views.py", line 486, in raise_uncaught_exception
    raise exc
  File "D:\DMS-GOA\vvenv\Lib\site-packages\rest_framework\views.py", line 512, in dispatch
    response = handler(request, *args, **kwargs)
               ^^^^^^^^^^^^^^^^^^^^^^^^^^^^^^^^^
  File "D:\DMS-GOA\DMS_goa\admin_web\views.py", line 435, in post
    serializer1.is_valid(raise_exception=True)
  File "D:\DMS-GOA\vvenv\Lib\site-packages\rest_framework\serializers.py", line 225, in is_valid
    self._validated_data = self.run_validation(self.initial_data)
                           ^^^^^^^^^^^^^^^^^^^^^^^^^^^^^^^^^^^^^^
  File "D:\DMS-GOA\vvenv\Lib\site-packages\rest_framework\serializers.py", line 447, in run_validation
    value = self.validate(value)
            ^^^^^^^^^^^^^^^^^^^^
  File "D:\DMS-GOA\DMS_goa\admin_web\serializers.py", line 237, in validate
    return super().validate(attrs)
           ^^^^^^^^^^^^^^^^^^^^^^^
  File "D:\DMS-GOA\vvenv\Lib\site-packages\rest_framework_simplejwt\serializers.py", line 75, in validate
    refresh = self.get_token(self.user)
              ^^^^^^^^^^^^^^^^^^^^^^^^^
  File "D:\DMS-GOA\vvenv\Lib\site-packages\rest_framework_simplejwt\serializers.py", line 66, in get_token
    return cls.token_class.for_user(user)  # type: ignore
           ^^^^^^^^^^^^^^^^^^^^^^^^^^^^^^
  File "D:\DMS-GOA\vvenv\Lib\site-packages\rest_framework_simplejwt\tokens.py", line 326, in for_user
    token = super().for_user(user)  # type: ignore
            ^^^^^^^^^^^^^^^^^^^^^^
  File "D:\DMS-GOA\vvenv\Lib\site-packages\rest_framework_simplejwt\tokens.py", line 238, in for_user
    user_id = getattr(user, api_settings.USER_ID_FIELD)
              ^^^^^^^^^^^^^^^^^^^^^^^^^^^^^^^^^^^^^^^^^
AttributeError: 'DMS_User' object has no attribute 'emp_id'. Did you mean: 'grp_id'?
ERROR 2025-08-11 16:17:38,885 basehttp "POST /admin_web/login/ HTTP/1.1" 500 124542
ERROR 2025-08-11 16:18:42,199 log Internal Server Error: /admin_web/login/
Traceback (most recent call last):
  File "D:\DMS-GOA\vvenv\Lib\site-packages\django\core\handlers\exception.py", line 55, in inner
    response = get_response(request)
               ^^^^^^^^^^^^^^^^^^^^^
  File "D:\DMS-GOA\vvenv\Lib\site-packages\django\core\handlers\base.py", line 197, in _get_response
    response = wrapped_callback(request, *callback_args, **callback_kwargs)
               ^^^^^^^^^^^^^^^^^^^^^^^^^^^^^^^^^^^^^^^^^^^^^^^^^^^^^^^^^^^^
  File "D:\DMS-GOA\vvenv\Lib\site-packages\django\views\decorators\csrf.py", line 65, in _view_wrapper
    return view_func(request, *args, **kwargs)
           ^^^^^^^^^^^^^^^^^^^^^^^^^^^^^^^^^^^
  File "D:\DMS-GOA\vvenv\Lib\site-packages\django\views\generic\base.py", line 105, in view
    return self.dispatch(request, *args, **kwargs)
           ^^^^^^^^^^^^^^^^^^^^^^^^^^^^^^^^^^^^^^^
  File "D:\DMS-GOA\vvenv\Lib\site-packages\rest_framework\views.py", line 515, in dispatch
    response = self.handle_exception(exc)
               ^^^^^^^^^^^^^^^^^^^^^^^^^^
  File "D:\DMS-GOA\vvenv\Lib\site-packages\rest_framework\views.py", line 475, in handle_exception
    self.raise_uncaught_exception(exc)
  File "D:\DMS-GOA\vvenv\Lib\site-packages\rest_framework\views.py", line 486, in raise_uncaught_exception
    raise exc
  File "D:\DMS-GOA\vvenv\Lib\site-packages\rest_framework\views.py", line 512, in dispatch
    response = handler(request, *args, **kwargs)
               ^^^^^^^^^^^^^^^^^^^^^^^^^^^^^^^^^
  File "D:\DMS-GOA\DMS_goa\admin_web\views.py", line 436, in post
    serializer1.is_valid(raise_exception=True)
  File "D:\DMS-GOA\vvenv\Lib\site-packages\rest_framework\serializers.py", line 225, in is_valid
    self._validated_data = self.run_validation(self.initial_data)
                           ^^^^^^^^^^^^^^^^^^^^^^^^^^^^^^^^^^^^^^
  File "D:\DMS-GOA\vvenv\Lib\site-packages\rest_framework\serializers.py", line 447, in run_validation
    value = self.validate(value)
            ^^^^^^^^^^^^^^^^^^^^
  File "D:\DMS-GOA\DMS_goa\admin_web\serializers.py", line 237, in validate
    return super().validate(attrs)
           ^^^^^^^^^^^^^^^^^^^^^^^
  File "D:\DMS-GOA\vvenv\Lib\site-packages\rest_framework_simplejwt\serializers.py", line 75, in validate
    refresh = self.get_token(self.user)
              ^^^^^^^^^^^^^^^^^^^^^^^^^
  File "D:\DMS-GOA\vvenv\Lib\site-packages\rest_framework_simplejwt\serializers.py", line 66, in get_token
    return cls.token_class.for_user(user)  # type: ignore
           ^^^^^^^^^^^^^^^^^^^^^^^^^^^^^^
  File "D:\DMS-GOA\vvenv\Lib\site-packages\rest_framework_simplejwt\tokens.py", line 326, in for_user
    token = super().for_user(user)  # type: ignore
            ^^^^^^^^^^^^^^^^^^^^^^
  File "D:\DMS-GOA\vvenv\Lib\site-packages\rest_framework_simplejwt\tokens.py", line 238, in for_user
    user_id = getattr(user, api_settings.USER_ID_FIELD)
              ^^^^^^^^^^^^^^^^^^^^^^^^^^^^^^^^^^^^^^^^^
AttributeError: 'DMS_User' object has no attribute 'emp_id'. Did you mean: 'grp_id'?
ERROR 2025-08-11 16:18:42,205 basehttp "POST /admin_web/login/ HTTP/1.1" 500 124596
WARNING 2025-08-11 16:20:08,579 log Bad Request: /admin_web/login/
WARNING 2025-08-11 16:20:08,580 basehttp "POST /admin_web/login/ HTTP/1.1" 400 54
ERROR 2025-08-11 16:20:35,680 log Internal Server Error: /admin_web/login/
Traceback (most recent call last):
  File "D:\DMS-GOA\vvenv\Lib\site-packages\django\core\handlers\exception.py", line 55, in inner
    response = get_response(request)
               ^^^^^^^^^^^^^^^^^^^^^
  File "D:\DMS-GOA\vvenv\Lib\site-packages\django\core\handlers\base.py", line 197, in _get_response
    response = wrapped_callback(request, *callback_args, **callback_kwargs)
               ^^^^^^^^^^^^^^^^^^^^^^^^^^^^^^^^^^^^^^^^^^^^^^^^^^^^^^^^^^^^
  File "D:\DMS-GOA\vvenv\Lib\site-packages\django\views\decorators\csrf.py", line 65, in _view_wrapper
    return view_func(request, *args, **kwargs)
           ^^^^^^^^^^^^^^^^^^^^^^^^^^^^^^^^^^^
  File "D:\DMS-GOA\vvenv\Lib\site-packages\django\views\generic\base.py", line 105, in view
    return self.dispatch(request, *args, **kwargs)
           ^^^^^^^^^^^^^^^^^^^^^^^^^^^^^^^^^^^^^^^
  File "D:\DMS-GOA\vvenv\Lib\site-packages\rest_framework\views.py", line 515, in dispatch
    response = self.handle_exception(exc)
               ^^^^^^^^^^^^^^^^^^^^^^^^^^
  File "D:\DMS-GOA\vvenv\Lib\site-packages\rest_framework\views.py", line 475, in handle_exception
    self.raise_uncaught_exception(exc)
  File "D:\DMS-GOA\vvenv\Lib\site-packages\rest_framework\views.py", line 486, in raise_uncaught_exception
    raise exc
  File "D:\DMS-GOA\vvenv\Lib\site-packages\rest_framework\views.py", line 512, in dispatch
    response = handler(request, *args, **kwargs)
               ^^^^^^^^^^^^^^^^^^^^^^^^^^^^^^^^^
  File "D:\DMS-GOA\DMS_goa\admin_web\views.py", line 436, in post
    serializer1.is_valid(raise_exception=True)
  File "D:\DMS-GOA\vvenv\Lib\site-packages\rest_framework\serializers.py", line 225, in is_valid
    self._validated_data = self.run_validation(self.initial_data)
                           ^^^^^^^^^^^^^^^^^^^^^^^^^^^^^^^^^^^^^^
  File "D:\DMS-GOA\vvenv\Lib\site-packages\rest_framework\serializers.py", line 447, in run_validation
    value = self.validate(value)
            ^^^^^^^^^^^^^^^^^^^^
  File "D:\DMS-GOA\DMS_goa\admin_web\serializers.py", line 237, in validate
    return super().validate(attrs)
           ^^^^^^^^^^^^^^^^^^^^^^^
  File "D:\DMS-GOA\vvenv\Lib\site-packages\rest_framework_simplejwt\serializers.py", line 75, in validate
    refresh = self.get_token(self.user)
              ^^^^^^^^^^^^^^^^^^^^^^^^^
  File "D:\DMS-GOA\vvenv\Lib\site-packages\rest_framework_simplejwt\serializers.py", line 66, in get_token
    return cls.token_class.for_user(user)  # type: ignore
           ^^^^^^^^^^^^^^^^^^^^^^^^^^^^^^
  File "D:\DMS-GOA\vvenv\Lib\site-packages\rest_framework_simplejwt\tokens.py", line 326, in for_user
    token = super().for_user(user)  # type: ignore
            ^^^^^^^^^^^^^^^^^^^^^^
  File "D:\DMS-GOA\vvenv\Lib\site-packages\rest_framework_simplejwt\tokens.py", line 238, in for_user
    user_id = getattr(user, api_settings.USER_ID_FIELD)
              ^^^^^^^^^^^^^^^^^^^^^^^^^^^^^^^^^^^^^^^^^
AttributeError: 'DMS_User' object has no attribute 'emp_id'. Did you mean: 'grp_id'?
ERROR 2025-08-11 16:20:35,686 basehttp "POST /admin_web/login/ HTTP/1.1" 500 124598
WARNING 2025-08-11 16:22:28,964 log Bad Request: /admin_web/login/
WARNING 2025-08-11 16:22:28,966 basehttp "POST /admin_web/login/ HTTP/1.1" 400 166
ERROR 2025-08-11 16:23:57,363 log Internal Server Error: /admin_web/login/
Traceback (most recent call last):
  File "D:\DMS-GOA\vvenv\Lib\site-packages\django\core\handlers\exception.py", line 55, in inner
    response = get_response(request)
               ^^^^^^^^^^^^^^^^^^^^^
  File "D:\DMS-GOA\vvenv\Lib\site-packages\django\core\handlers\base.py", line 197, in _get_response
    response = wrapped_callback(request, *callback_args, **callback_kwargs)
               ^^^^^^^^^^^^^^^^^^^^^^^^^^^^^^^^^^^^^^^^^^^^^^^^^^^^^^^^^^^^
  File "D:\DMS-GOA\vvenv\Lib\site-packages\django\views\decorators\csrf.py", line 65, in _view_wrapper
    return view_func(request, *args, **kwargs)
           ^^^^^^^^^^^^^^^^^^^^^^^^^^^^^^^^^^^
  File "D:\DMS-GOA\vvenv\Lib\site-packages\django\views\generic\base.py", line 105, in view
    return self.dispatch(request, *args, **kwargs)
           ^^^^^^^^^^^^^^^^^^^^^^^^^^^^^^^^^^^^^^^
  File "D:\DMS-GOA\vvenv\Lib\site-packages\rest_framework\views.py", line 515, in dispatch
    response = self.handle_exception(exc)
               ^^^^^^^^^^^^^^^^^^^^^^^^^^
  File "D:\DMS-GOA\vvenv\Lib\site-packages\rest_framework\views.py", line 475, in handle_exception
    self.raise_uncaught_exception(exc)
  File "D:\DMS-GOA\vvenv\Lib\site-packages\rest_framework\views.py", line 486, in raise_uncaught_exception
    raise exc
  File "D:\DMS-GOA\vvenv\Lib\site-packages\rest_framework\views.py", line 512, in dispatch
    response = handler(request, *args, **kwargs)
               ^^^^^^^^^^^^^^^^^^^^^^^^^^^^^^^^^
  File "D:\DMS-GOA\DMS_goa\admin_web\views.py", line 457, in post
    token = get_tokens_for_user(user , login_entry_obj.log_id)
            ^^^^^^^^^^^^^^^^^^^^^^^^^^^^^^^^^^^^^^^^^^^^^^^^^^
  File "D:\DMS-GOA\DMS_goa\admin_web\views.py", line 391, in get_tokens_for_user
    refresh = RefreshToken.for_user(user)
              ^^^^^^^^^^^^^^^^^^^^^^^^^^^
  File "D:\DMS-GOA\vvenv\Lib\site-packages\rest_framework_simplejwt\tokens.py", line 326, in for_user
    token = super().for_user(user)  # type: ignore
            ^^^^^^^^^^^^^^^^^^^^^^
  File "D:\DMS-GOA\vvenv\Lib\site-packages\rest_framework_simplejwt\tokens.py", line 238, in for_user
    user_id = getattr(user, api_settings.USER_ID_FIELD)
              ^^^^^^^^^^^^^^^^^^^^^^^^^^^^^^^^^^^^^^^^^
AttributeError: 'DMS_User' object has no attribute 'emp_id'. Did you mean: 'grp_id'?
ERROR 2025-08-11 16:23:57,367 basehttp "POST /admin_web/login/ HTTP/1.1" 500 106951
ERROR 2025-08-11 16:27:34,737 log Internal Server Error: /admin_web/login/
Traceback (most recent call last):
  File "D:\DMS-GOA\vvenv\Lib\site-packages\django\core\handlers\exception.py", line 55, in inner
    response = get_response(request)
               ^^^^^^^^^^^^^^^^^^^^^
  File "D:\DMS-GOA\vvenv\Lib\site-packages\django\core\handlers\base.py", line 197, in _get_response
    response = wrapped_callback(request, *callback_args, **callback_kwargs)
               ^^^^^^^^^^^^^^^^^^^^^^^^^^^^^^^^^^^^^^^^^^^^^^^^^^^^^^^^^^^^
  File "D:\DMS-GOA\vvenv\Lib\site-packages\django\views\decorators\csrf.py", line 65, in _view_wrapper
    return view_func(request, *args, **kwargs)
           ^^^^^^^^^^^^^^^^^^^^^^^^^^^^^^^^^^^
  File "D:\DMS-GOA\vvenv\Lib\site-packages\django\views\generic\base.py", line 105, in view
    return self.dispatch(request, *args, **kwargs)
           ^^^^^^^^^^^^^^^^^^^^^^^^^^^^^^^^^^^^^^^
  File "D:\DMS-GOA\vvenv\Lib\site-packages\rest_framework\views.py", line 515, in dispatch
    response = self.handle_exception(exc)
               ^^^^^^^^^^^^^^^^^^^^^^^^^^
  File "D:\DMS-GOA\vvenv\Lib\site-packages\rest_framework\views.py", line 475, in handle_exception
    self.raise_uncaught_exception(exc)
  File "D:\DMS-GOA\vvenv\Lib\site-packages\rest_framework\views.py", line 486, in raise_uncaught_exception
    raise exc
  File "D:\DMS-GOA\vvenv\Lib\site-packages\rest_framework\views.py", line 512, in dispatch
    response = handler(request, *args, **kwargs)
               ^^^^^^^^^^^^^^^^^^^^^^^^^^^^^^^^^
  File "D:\DMS-GOA\DMS_goa\admin_web\views.py", line 436, in post
    serializer1.is_valid(raise_exception=True)
  File "D:\DMS-GOA\vvenv\Lib\site-packages\rest_framework\serializers.py", line 225, in is_valid
    self._validated_data = self.run_validation(self.initial_data)
                           ^^^^^^^^^^^^^^^^^^^^^^^^^^^^^^^^^^^^^^
  File "D:\DMS-GOA\vvenv\Lib\site-packages\rest_framework\serializers.py", line 447, in run_validation
    value = self.validate(value)
            ^^^^^^^^^^^^^^^^^^^^
  File "D:\DMS-GOA\DMS_goa\admin_web\serializers.py", line 237, in validate
    return super().validate(attrs)
           ^^^^^^^^^^^^^^^^^^^^^^^
  File "D:\DMS-GOA\vvenv\Lib\site-packages\rest_framework_simplejwt\serializers.py", line 75, in validate
    refresh = self.get_token(self.user)
              ^^^^^^^^^^^^^^^^^^^^^^^^^
  File "D:\DMS-GOA\vvenv\Lib\site-packages\rest_framework_simplejwt\serializers.py", line 66, in get_token
    return cls.token_class.for_user(user)  # type: ignore
           ^^^^^^^^^^^^^^^^^^^^^^^^^^^^^^
  File "D:\DMS-GOA\vvenv\Lib\site-packages\rest_framework_simplejwt\tokens.py", line 326, in for_user
    token = super().for_user(user)  # type: ignore
            ^^^^^^^^^^^^^^^^^^^^^^
  File "D:\DMS-GOA\vvenv\Lib\site-packages\rest_framework_simplejwt\tokens.py", line 238, in for_user
    user_id = getattr(user, api_settings.USER_ID_FIELD)
              ^^^^^^^^^^^^^^^^^^^^^^^^^^^^^^^^^^^^^^^^^
AttributeError: 'DMS_User' object has no attribute 'emp_id'. Did you mean: 'grp_id'?
ERROR 2025-08-11 16:27:34,751 basehttp "POST /admin_web/login/ HTTP/1.1" 500 124598
WARNING 2025-08-11 16:29:10,919 log Bad Request: /admin_web/login/
WARNING 2025-08-11 16:29:10,920 basehttp "POST /admin_web/login/ HTTP/1.1" 400 149
WARNING 2025-08-11 16:29:43,229 log Bad Request: /admin_web/login/
WARNING 2025-08-11 16:29:43,230 basehttp "POST /admin_web/login/ HTTP/1.1" 400 98
WARNING 2025-08-11 16:31:08,600 log Bad Request: /admin_web/login/
WARNING 2025-08-11 16:31:08,600 basehttp "POST /admin_web/login/ HTTP/1.1" 400 98
WARNING 2025-08-11 16:31:39,847 log Bad Request: /admin_web/login/
WARNING 2025-08-11 16:31:39,848 basehttp "POST /admin_web/login/ HTTP/1.1" 400 98
WARNING 2025-08-11 16:33:08,227 log Bad Request: /admin_web/login/
WARNING 2025-08-11 16:33:08,228 basehttp "POST /admin_web/login/ HTTP/1.1" 400 98
ERROR 2025-08-11 16:36:03,481 log Internal Server Error: /admin_web/login/
ERROR 2025-08-11 16:36:03,482 basehttp "POST /admin_web/login/ HTTP/1.1" 500 54
ERROR 2025-08-11 16:37:29,046 log Internal Server Error: /admin_web/login/
ERROR 2025-08-11 16:37:29,046 basehttp "POST /admin_web/login/ HTTP/1.1" 500 54
ERROR 2025-08-11 16:42:15,635 log Internal Server Error: /admin_web/login/
ERROR 2025-08-11 16:42:15,636 basehttp "POST /admin_web/login/ HTTP/1.1" 500 54
ERROR 2025-08-11 16:44:20,769 log Internal Server Error: /admin_web/login/
ERROR 2025-08-11 16:44:20,769 basehttp "POST /admin_web/login/ HTTP/1.1" 500 54
ERROR 2025-08-11 16:46:00,456 log Internal Server Error: /admin_web/login/
Traceback (most recent call last):
  File "D:\DMS-GOA\vvenv\Lib\site-packages\django\core\handlers\exception.py", line 55, in inner
    response = get_response(request)
               ^^^^^^^^^^^^^^^^^^^^^
  File "D:\DMS-GOA\vvenv\Lib\site-packages\django\core\handlers\base.py", line 220, in _get_response
    response = response.render()
               ^^^^^^^^^^^^^^^^^
  File "D:\DMS-GOA\vvenv\Lib\site-packages\django\template\response.py", line 114, in render
    self.content = self.rendered_content
                   ^^^^^^^^^^^^^^^^^^^^^
  File "D:\DMS-GOA\vvenv\Lib\site-packages\rest_framework\response.py", line 74, in rendered_content
    ret = renderer.render(self.data, accepted_media_type, context)
          ^^^^^^^^^^^^^^^^^^^^^^^^^^^^^^^^^^^^^^^^^^^^^^^^^^^^^^^^
  File "D:\DMS-GOA\DMS_goa\admin_web\renders.py", line 11, in render
    response = json.dumps(data)
               ^^^^^^^^^^^^^^^^
  File "C:\Users\admin\AppData\Local\Programs\Python\Python312\Lib\json\__init__.py", line 231, in dumps
    return _default_encoder.encode(obj)
           ^^^^^^^^^^^^^^^^^^^^^^^^^^^^
  File "C:\Users\admin\AppData\Local\Programs\Python\Python312\Lib\json\encoder.py", line 200, in encode
    chunks = self.iterencode(o, _one_shot=True)
             ^^^^^^^^^^^^^^^^^^^^^^^^^^^^^^^^^^
  File "C:\Users\admin\AppData\Local\Programs\Python\Python312\Lib\json\encoder.py", line 258, in iterencode
    return _iterencode(o, 0)
           ^^^^^^^^^^^^^^^^^
  File "C:\Users\admin\AppData\Local\Programs\Python\Python312\Lib\json\encoder.py", line 180, in default
    raise TypeError(f'Object of type {o.__class__.__name__} '
TypeError: Object of type Response is not JSON serializable
ERROR 2025-08-11 16:46:00,461 basehttp "POST /admin_web/login/ HTTP/1.1" 500 94343
ERROR 2025-08-11 16:48:24,339 log Internal Server Error: /admin_web/login/
Traceback (most recent call last):
  File "D:\DMS-GOA\vvenv\Lib\site-packages\django\core\handlers\exception.py", line 55, in inner
    response = get_response(request)
               ^^^^^^^^^^^^^^^^^^^^^
  File "D:\DMS-GOA\vvenv\Lib\site-packages\django\core\handlers\base.py", line 220, in _get_response
    response = response.render()
               ^^^^^^^^^^^^^^^^^
  File "D:\DMS-GOA\vvenv\Lib\site-packages\django\template\response.py", line 114, in render
    self.content = self.rendered_content
                   ^^^^^^^^^^^^^^^^^^^^^
  File "D:\DMS-GOA\vvenv\Lib\site-packages\rest_framework\response.py", line 74, in rendered_content
    ret = renderer.render(self.data, accepted_media_type, context)
          ^^^^^^^^^^^^^^^^^^^^^^^^^^^^^^^^^^^^^^^^^^^^^^^^^^^^^^^^
  File "D:\DMS-GOA\DMS_goa\admin_web\renders.py", line 11, in render
    response = json.dumps(data)
               ^^^^^^^^^^^^^^^^
  File "C:\Users\admin\AppData\Local\Programs\Python\Python312\Lib\json\__init__.py", line 231, in dumps
    return _default_encoder.encode(obj)
           ^^^^^^^^^^^^^^^^^^^^^^^^^^^^
  File "C:\Users\admin\AppData\Local\Programs\Python\Python312\Lib\json\encoder.py", line 200, in encode
    chunks = self.iterencode(o, _one_shot=True)
             ^^^^^^^^^^^^^^^^^^^^^^^^^^^^^^^^^^
  File "C:\Users\admin\AppData\Local\Programs\Python\Python312\Lib\json\encoder.py", line 258, in iterencode
    return _iterencode(o, 0)
           ^^^^^^^^^^^^^^^^^
  File "C:\Users\admin\AppData\Local\Programs\Python\Python312\Lib\json\encoder.py", line 180, in default
    raise TypeError(f'Object of type {o.__class__.__name__} '
TypeError: Object of type Response is not JSON serializable
ERROR 2025-08-11 16:48:24,342 basehttp "POST /admin_web/login/ HTTP/1.1" 500 94343
ERROR 2025-08-11 16:49:56,881 log Internal Server Error: /admin_web/login/
Traceback (most recent call last):
  File "D:\DMS-GOA\vvenv\Lib\site-packages\django\core\handlers\exception.py", line 55, in inner
    response = get_response(request)
               ^^^^^^^^^^^^^^^^^^^^^
  File "D:\DMS-GOA\vvenv\Lib\site-packages\django\core\handlers\base.py", line 220, in _get_response
    response = response.render()
               ^^^^^^^^^^^^^^^^^
  File "D:\DMS-GOA\vvenv\Lib\site-packages\django\template\response.py", line 114, in render
    self.content = self.rendered_content
                   ^^^^^^^^^^^^^^^^^^^^^
  File "D:\DMS-GOA\vvenv\Lib\site-packages\rest_framework\response.py", line 74, in rendered_content
    ret = renderer.render(self.data, accepted_media_type, context)
          ^^^^^^^^^^^^^^^^^^^^^^^^^^^^^^^^^^^^^^^^^^^^^^^^^^^^^^^^
  File "D:\DMS-GOA\DMS_goa\admin_web\renders.py", line 11, in render
    response = json.dumps(data)
               ^^^^^^^^^^^^^^^^
  File "C:\Users\admin\AppData\Local\Programs\Python\Python312\Lib\json\__init__.py", line 231, in dumps
    return _default_encoder.encode(obj)
           ^^^^^^^^^^^^^^^^^^^^^^^^^^^^
  File "C:\Users\admin\AppData\Local\Programs\Python\Python312\Lib\json\encoder.py", line 200, in encode
    chunks = self.iterencode(o, _one_shot=True)
             ^^^^^^^^^^^^^^^^^^^^^^^^^^^^^^^^^^
  File "C:\Users\admin\AppData\Local\Programs\Python\Python312\Lib\json\encoder.py", line 258, in iterencode
    return _iterencode(o, 0)
           ^^^^^^^^^^^^^^^^^
  File "C:\Users\admin\AppData\Local\Programs\Python\Python312\Lib\json\encoder.py", line 180, in default
    raise TypeError(f'Object of type {o.__class__.__name__} '
TypeError: Object of type Response is not JSON serializable
ERROR 2025-08-11 16:49:56,884 basehttp "POST /admin_web/login/ HTTP/1.1" 500 94343
ERROR 2025-08-11 16:54:47,428 log Internal Server Error: /admin_web/login/
ERROR 2025-08-11 16:54:47,428 basehttp "POST /admin_web/login/ HTTP/1.1" 500 54
ERROR 2025-08-11 17:01:28,349 log Internal Server Error: /admin_web/login/
ERROR 2025-08-11 17:01:28,349 basehttp "POST /admin_web/login/ HTTP/1.1" 500 54
ERROR 2025-08-11 17:08:53,938 log Internal Server Error: /admin_web/login/
ERROR 2025-08-11 17:08:53,938 basehttp "POST /admin_web/login/ HTTP/1.1" 500 54
ERROR 2025-08-11 17:09:45,640 log Internal Server Error: /admin_web/login/
ERROR 2025-08-11 17:09:45,640 basehttp "POST /admin_web/login/ HTTP/1.1" 500 54
ERROR 2025-08-11 17:10:45,667 log Internal Server Error: /admin_web/login/
ERROR 2025-08-11 17:10:45,668 basehttp "POST /admin_web/login/ HTTP/1.1" 500 54
ERROR 2025-08-11 17:11:34,455 log Internal Server Error: /admin_web/login/
ERROR 2025-08-11 17:11:34,456 basehttp "POST /admin_web/login/ HTTP/1.1" 500 54
ERROR 2025-08-11 17:12:54,678 log Internal Server Error: /admin_web/login/
ERROR 2025-08-11 17:12:54,681 basehttp "POST /admin_web/login/ HTTP/1.1" 500 54
ERROR 2025-08-11 17:13:32,378 log Internal Server Error: /admin_web/login/
ERROR 2025-08-11 17:13:32,380 basehttp "POST /admin_web/login/ HTTP/1.1" 500 54
ERROR 2025-08-11 17:17:01,691 log Internal Server Error: /admin_web/login/
ERROR 2025-08-11 17:17:01,691 basehttp "POST /admin_web/login/ HTTP/1.1" 500 54
ERROR 2025-08-11 17:19:26,175 log Internal Server Error: /admin_web/login/
ERROR 2025-08-11 17:19:26,176 basehttp "POST /admin_web/login/ HTTP/1.1" 500 55
WARNING 2025-08-11 17:27:02,438 log Bad Request: /admin_web/login/
WARNING 2025-08-11 17:27:02,439 basehttp "POST /admin_web/login/ HTTP/1.1" 400 166
ERROR 2025-08-11 17:28:29,154 log Internal Server Error: /admin_web/login/
Traceback (most recent call last):
  File "D:\DMS-GOA\vvenv\Lib\site-packages\django\core\handlers\exception.py", line 55, in inner
    response = get_response(request)
               ^^^^^^^^^^^^^^^^^^^^^
  File "D:\DMS-GOA\vvenv\Lib\site-packages\django\core\handlers\base.py", line 197, in _get_response
    response = wrapped_callback(request, *callback_args, **callback_kwargs)
               ^^^^^^^^^^^^^^^^^^^^^^^^^^^^^^^^^^^^^^^^^^^^^^^^^^^^^^^^^^^^
  File "D:\DMS-GOA\vvenv\Lib\site-packages\django\views\decorators\csrf.py", line 65, in _view_wrapper
    return view_func(request, *args, **kwargs)
           ^^^^^^^^^^^^^^^^^^^^^^^^^^^^^^^^^^^
  File "D:\DMS-GOA\vvenv\Lib\site-packages\django\views\generic\base.py", line 105, in view
    return self.dispatch(request, *args, **kwargs)
           ^^^^^^^^^^^^^^^^^^^^^^^^^^^^^^^^^^^^^^^
  File "D:\DMS-GOA\vvenv\Lib\site-packages\rest_framework\views.py", line 515, in dispatch
    response = self.handle_exception(exc)
               ^^^^^^^^^^^^^^^^^^^^^^^^^^
  File "D:\DMS-GOA\vvenv\Lib\site-packages\rest_framework\views.py", line 475, in handle_exception
    self.raise_uncaught_exception(exc)
  File "D:\DMS-GOA\vvenv\Lib\site-packages\rest_framework\views.py", line 486, in raise_uncaught_exception
    raise exc
  File "D:\DMS-GOA\vvenv\Lib\site-packages\rest_framework\views.py", line 512, in dispatch
    response = handler(request, *args, **kwargs)
               ^^^^^^^^^^^^^^^^^^^^^^^^^^^^^^^^^
  File "D:\DMS-GOA\DMS_goa\admin_web\views.py", line 455, in post
    token = get_tokens_for_user(user , login_entry_obj.log_id)
            ^^^^^^^^^^^^^^^^^^^^^^^^^^^^^^^^^^^^^^^^^^^^^^^^^^
  File "D:\DMS-GOA\DMS_goa\admin_web\views.py", line 391, in get_tokens_for_user
    emp_obj = DMS_Employee.objects.get(user_id=user.user_id)
              ^^^^^^^^^^^^^^^^^^^^^^^^^^^^^^^^^^^^^^^^^^^^^^
  File "D:\DMS-GOA\vvenv\Lib\site-packages\django\db\models\manager.py", line 87, in manager_method
    return getattr(self.get_queryset(), name)(*args, **kwargs)
           ^^^^^^^^^^^^^^^^^^^^^^^^^^^^^^^^^^^^^^^^^^^^^^^^^^^
  File "D:\DMS-GOA\vvenv\Lib\site-packages\django\db\models\query.py", line 633, in get
    raise self.model.DoesNotExist(
admin_web.models.DMS_Employee.DoesNotExist: DMS_Employee matching query does not exist.
ERROR 2025-08-11 17:28:29,172 basehttp "POST /admin_web/login/ HTTP/1.1" 500 108515
WARNING 2025-08-11 17:35:18,089 log Bad Request: /admin_web/login/
WARNING 2025-08-11 17:35:18,089 basehttp "POST /admin_web/login/ HTTP/1.1" 400 58
WARNING 2025-08-11 17:54:24,077 log Not Found: /favicon.ico
WARNING 2025-08-11 17:54:24,085 basehttp "GET /favicon.ico HTTP/1.1" 404 2833
WARNING 2025-08-11 17:55:55,259 log Bad Request: /admin_web/login/
WARNING 2025-08-11 17:55:55,259 basehttp "POST /admin_web/login/ HTTP/1.1" 400 58
WARNING 2025-08-11 17:59:52,020 log Bad Request: /admin_web/login/
WARNING 2025-08-11 17:59:52,020 basehttp "POST /admin_web/login/ HTTP/1.1" 400 58
ERROR 2025-08-25 13:14:33,495 log Internal Server Error: /admin_web/get_responder_list/5/
Traceback (most recent call last):
  File "D:\DMS-GOA\vvenv\Lib\site-packages\django\db\models\fields\__init__.py", line 2128, in get_prep_value
    return int(value)
           ^^^^^^^^^^
TypeError: int() argument must be a string, a bytes-like object or a real number, not 'Query'

The above exception was the direct cause of the following exception:

Traceback (most recent call last):
  File "D:\DMS-GOA\vvenv\Lib\site-packages\django\core\handlers\exception.py", line 55, in inner
    response = get_response(request)
               ^^^^^^^^^^^^^^^^^^^^^
  File "D:\DMS-GOA\vvenv\Lib\site-packages\django\core\handlers\base.py", line 197, in _get_response
    response = wrapped_callback(request, *callback_args, **callback_kwargs)
               ^^^^^^^^^^^^^^^^^^^^^^^^^^^^^^^^^^^^^^^^^^^^^^^^^^^^^^^^^^^^
  File "D:\DMS-GOA\vvenv\Lib\site-packages\django\views\decorators\csrf.py", line 65, in _view_wrapper
    return view_func(request, *args, **kwargs)
           ^^^^^^^^^^^^^^^^^^^^^^^^^^^^^^^^^^^
  File "D:\DMS-GOA\vvenv\Lib\site-packages\django\views\generic\base.py", line 105, in view
    return self.dispatch(request, *args, **kwargs)
           ^^^^^^^^^^^^^^^^^^^^^^^^^^^^^^^^^^^^^^^
  File "D:\DMS-GOA\vvenv\Lib\site-packages\rest_framework\views.py", line 515, in dispatch
    response = self.handle_exception(exc)
               ^^^^^^^^^^^^^^^^^^^^^^^^^^
  File "D:\DMS-GOA\vvenv\Lib\site-packages\rest_framework\views.py", line 475, in handle_exception
    self.raise_uncaught_exception(exc)
  File "D:\DMS-GOA\vvenv\Lib\site-packages\rest_framework\views.py", line 486, in raise_uncaught_exception
    raise exc
  File "D:\DMS-GOA\vvenv\Lib\site-packages\rest_framework\views.py", line 512, in dispatch
    response = handler(request, *args, **kwargs)
               ^^^^^^^^^^^^^^^^^^^^^^^^^^^^^^^^^
  File "D:\DMS-GOA\DMS_goa\admin_web\views.py", line 1657, in get
    inc_ws_ve = incident_wise_vehicle.objects.filter(incident_id=inc_id,veh_id__responder__in=res_lst, status=False)
                ^^^^^^^^^^^^^^^^^^^^^^^^^^^^^^^^^^^^^^^^^^^^^^^^^^^^^^^^^^^^^^^^^^^^^^^^^^^^^^^^^^^^^^^^^^^^^^^^^^^^
  File "D:\DMS-GOA\vvenv\Lib\site-packages\django\db\models\manager.py", line 87, in manager_method
    return getattr(self.get_queryset(), name)(*args, **kwargs)
           ^^^^^^^^^^^^^^^^^^^^^^^^^^^^^^^^^^^^^^^^^^^^^^^^^^^
  File "D:\DMS-GOA\vvenv\Lib\site-packages\django\db\models\query.py", line 1493, in filter
    return self._filter_or_exclude(False, args, kwargs)
           ^^^^^^^^^^^^^^^^^^^^^^^^^^^^^^^^^^^^^^^^^^^^
  File "D:\DMS-GOA\vvenv\Lib\site-packages\django\db\models\query.py", line 1511, in _filter_or_exclude
    clone._filter_or_exclude_inplace(negate, args, kwargs)
  File "D:\DMS-GOA\vvenv\Lib\site-packages\django\db\models\query.py", line 1518, in _filter_or_exclude_inplace
    self._query.add_q(Q(*args, **kwargs))
  File "D:\DMS-GOA\vvenv\Lib\site-packages\django\db\models\sql\query.py", line 1646, in add_q
    clause, _ = self._add_q(q_object, can_reuse)
                ^^^^^^^^^^^^^^^^^^^^^^^^^^^^^^^^
  File "D:\DMS-GOA\vvenv\Lib\site-packages\django\db\models\sql\query.py", line 1678, in _add_q
    child_clause, needed_inner = self.build_filter(
                                 ^^^^^^^^^^^^^^^^^^
  File "D:\DMS-GOA\vvenv\Lib\site-packages\django\db\models\sql\query.py", line 1588, in build_filter
    condition = self.build_lookup(lookups, col, value)
                ^^^^^^^^^^^^^^^^^^^^^^^^^^^^^^^^^^^^^^
  File "D:\DMS-GOA\vvenv\Lib\site-packages\django\db\models\sql\query.py", line 1415, in build_lookup
    lookup = lookup_class(lhs, rhs)
             ^^^^^^^^^^^^^^^^^^^^^^
  File "D:\DMS-GOA\vvenv\Lib\site-packages\django\db\models\lookups.py", line 38, in __init__
    self.rhs = self.get_prep_lookup()
               ^^^^^^^^^^^^^^^^^^^^^^
  File "D:\DMS-GOA\vvenv\Lib\site-packages\django\db\models\fields\related_lookups.py", line 67, in get_prep_lookup
    self.rhs = [target_field.get_prep_value(v) for v in self.rhs]
                ^^^^^^^^^^^^^^^^^^^^^^^^^^^^^^
  File "D:\DMS-GOA\vvenv\Lib\site-packages\django\db\models\fields\__init__.py", line 2130, in get_prep_value
    raise e.__class__(
TypeError: Field 'responder_id' expected a number but got <django.db.models.sql.query.Query object at 0x000001FFA08CC770>.
ERROR 2025-08-25 13:14:33,516 basehttp "GET /admin_web/get_responder_list/5/ HTTP/1.1" 500 160145
WARNING 2025-08-25 13:14:33,811 log Not Found: /favicon.ico
WARNING 2025-08-25 13:14:33,817 basehttp "GET /favicon.ico HTTP/1.1" 404 2833
ERROR 2025-08-25 14:29:00,017 log Internal Server Error: /admin_web/get_responder_list/5/
Traceback (most recent call last):
  File "D:\DMS-GOA\vvenv\Lib\site-packages\django\db\models\sql\query.py", line 1923, in transform
    return self.try_transform(wrapped, name)
           ^^^^^^^^^^^^^^^^^^^^^^^^^^^^^^^^^
  File "D:\DMS-GOA\vvenv\Lib\site-packages\django\db\models\sql\query.py", line 1458, in try_transform
    raise FieldError(
django.core.exceptions.FieldError: Unsupported lookup 'vehicle_no' for CharField or join on the field not permitted.

During handling of the above exception, another exception occurred:

Traceback (most recent call last):
  File "D:\DMS-GOA\vvenv\Lib\site-packages\django\core\handlers\exception.py", line 55, in inner
    response = get_response(request)
               ^^^^^^^^^^^^^^^^^^^^^
  File "D:\DMS-GOA\vvenv\Lib\site-packages\django\core\handlers\base.py", line 197, in _get_response
    response = wrapped_callback(request, *callback_args, **callback_kwargs)
               ^^^^^^^^^^^^^^^^^^^^^^^^^^^^^^^^^^^^^^^^^^^^^^^^^^^^^^^^^^^^
  File "D:\DMS-GOA\vvenv\Lib\site-packages\django\views\decorators\csrf.py", line 65, in _view_wrapper
    return view_func(request, *args, **kwargs)
           ^^^^^^^^^^^^^^^^^^^^^^^^^^^^^^^^^^^
  File "D:\DMS-GOA\vvenv\Lib\site-packages\django\views\generic\base.py", line 105, in view
    return self.dispatch(request, *args, **kwargs)
           ^^^^^^^^^^^^^^^^^^^^^^^^^^^^^^^^^^^^^^^
  File "D:\DMS-GOA\vvenv\Lib\site-packages\rest_framework\views.py", line 515, in dispatch
    response = self.handle_exception(exc)
               ^^^^^^^^^^^^^^^^^^^^^^^^^^
  File "D:\DMS-GOA\vvenv\Lib\site-packages\rest_framework\views.py", line 475, in handle_exception
    self.raise_uncaught_exception(exc)
  File "D:\DMS-GOA\vvenv\Lib\site-packages\rest_framework\views.py", line 486, in raise_uncaught_exception
    raise exc
  File "D:\DMS-GOA\vvenv\Lib\site-packages\rest_framework\views.py", line 512, in dispatch
    response = handler(request, *args, **kwargs)
               ^^^^^^^^^^^^^^^^^^^^^^^^^^^^^^^^^
  File "D:\DMS-GOA\DMS_goa\admin_web\views.py", line 1671, in get
    vehicle_no__in=inc_ws_ve.values_list('veh_id__vehicle_no', flat=True)
                   ^^^^^^^^^^^^^^^^^^^^^^^^^^^^^^^^^^^^^^^^^^^^^^^^^^^^^^
  File "D:\DMS-GOA\vvenv\Lib\site-packages\django\db\models\query.py", line 1409, in values_list
    clone = self._values(*_fields, **expressions)
            ^^^^^^^^^^^^^^^^^^^^^^^^^^^^^^^^^^^^^
  File "D:\DMS-GOA\vvenv\Lib\site-packages\django\db\models\query.py", line 1363, in _values
    clone.query.set_values(fields)
  File "D:\DMS-GOA\vvenv\Lib\site-packages\django\db\models\sql\query.py", line 2563, in set_values
    self.add_fields(field_names, True)
  File "D:\DMS-GOA\vvenv\Lib\site-packages\django\db\models\sql\query.py", line 2246, in add_fields
    cols.append(join_info.transform_function(target, final_alias))
                ^^^^^^^^^^^^^^^^^^^^^^^^^^^^^^^^^^^^^^^^^^^^^^^^^
  File "D:\DMS-GOA\vvenv\Lib\site-packages\django\db\models\sql\query.py", line 1927, in transform
    raise last_field_exception
  File "D:\DMS-GOA\vvenv\Lib\site-packages\django\db\models\sql\query.py", line 1900, in setup_joins
    path, final_field, targets, rest = self.names_to_path(
                                       ^^^^^^^^^^^^^^^^^^^
  File "D:\DMS-GOA\vvenv\Lib\site-packages\django\db\models\sql\query.py", line 1805, in names_to_path
    raise FieldError(
django.core.exceptions.FieldError: Cannot resolve keyword 'vehicle_no' into field. Choices are: dep_id, dep_id_id, dms_incident_closure, employee_clockin_info, incident_vehicles, incident_wise_vehicle, responder, responder_id, status, user, user_id, veh_added_by, veh_added_date, veh_address, veh_app_lat, veh_app_log, veh_base_location, veh_base_location_id, veh_city, veh_city_id, veh_default_mobile, veh_district, veh_district_id, veh_gps_lat, veh_gps_log, veh_hash, veh_id, veh_modify_by, veh_modify_date, veh_number, veh_state, veh_state_id, veh_tahsil, veh_tahsil_id, veh_ward_id, veh_ward_id_id, vehical_status, vehicle_login_info, vehis_login
ERROR 2025-08-25 14:29:00,026 basehttp "GET /admin_web/get_responder_list/5/ HTTP/1.1" 500 159047
WARNING 2025-08-25 14:29:00,235 log Not Found: /favicon.ico
WARNING 2025-08-25 14:29:00,235 basehttp "GET /favicon.ico HTTP/1.1" 404 2833
ERROR 2025-08-25 15:19:20,162 log Internal Server Error: /admin_web/get_responder_list/5/
Traceback (most recent call last):
  File "D:\DMS-GOA\vvenv\Lib\site-packages\django\db\models\fields\__init__.py", line 2128, in get_prep_value
    return int(value)
           ^^^^^^^^^^
TypeError: int() argument must be a string, a bytes-like object or a real number, not 'Query'

The above exception was the direct cause of the following exception:

Traceback (most recent call last):
  File "D:\DMS-GOA\vvenv\Lib\site-packages\django\core\handlers\exception.py", line 55, in inner
    response = get_response(request)
               ^^^^^^^^^^^^^^^^^^^^^
  File "D:\DMS-GOA\vvenv\Lib\site-packages\django\core\handlers\base.py", line 197, in _get_response
    response = wrapped_callback(request, *callback_args, **callback_kwargs)
               ^^^^^^^^^^^^^^^^^^^^^^^^^^^^^^^^^^^^^^^^^^^^^^^^^^^^^^^^^^^^
  File "D:\DMS-GOA\vvenv\Lib\site-packages\django\views\decorators\csrf.py", line 65, in _view_wrapper
    return view_func(request, *args, **kwargs)
           ^^^^^^^^^^^^^^^^^^^^^^^^^^^^^^^^^^^
  File "D:\DMS-GOA\vvenv\Lib\site-packages\django\views\generic\base.py", line 105, in view
    return self.dispatch(request, *args, **kwargs)
           ^^^^^^^^^^^^^^^^^^^^^^^^^^^^^^^^^^^^^^^
  File "D:\DMS-GOA\vvenv\Lib\site-packages\rest_framework\views.py", line 515, in dispatch
    response = self.handle_exception(exc)
               ^^^^^^^^^^^^^^^^^^^^^^^^^^
  File "D:\DMS-GOA\vvenv\Lib\site-packages\rest_framework\views.py", line 475, in handle_exception
    self.raise_uncaught_exception(exc)
  File "D:\DMS-GOA\vvenv\Lib\site-packages\rest_framework\views.py", line 486, in raise_uncaught_exception
    raise exc
  File "D:\DMS-GOA\vvenv\Lib\site-packages\rest_framework\views.py", line 512, in dispatch
    response = handler(request, *args, **kwargs)
               ^^^^^^^^^^^^^^^^^^^^^^^^^^^^^^^^^
  File "D:\DMS-GOA\DMS_goa\admin_web\views.py", line 1657, in get
    inc_ws_ve = incident_wise_vehicle.objects.filter(incident_id=inc_id,veh_id__responder__in=res_lst, status=False)
                ^^^^^^^^^^^^^^^^^^^^^^^^^^^^^^^^^^^^^^^^^^^^^^^^^^^^^^^^^^^^^^^^^^^^^^^^^^^^^^^^^^^^^^^^^^^^^^^^^^^^
  File "D:\DMS-GOA\vvenv\Lib\site-packages\django\db\models\manager.py", line 87, in manager_method
    return getattr(self.get_queryset(), name)(*args, **kwargs)
           ^^^^^^^^^^^^^^^^^^^^^^^^^^^^^^^^^^^^^^^^^^^^^^^^^^^
  File "D:\DMS-GOA\vvenv\Lib\site-packages\django\db\models\query.py", line 1493, in filter
    return self._filter_or_exclude(False, args, kwargs)
           ^^^^^^^^^^^^^^^^^^^^^^^^^^^^^^^^^^^^^^^^^^^^
  File "D:\DMS-GOA\vvenv\Lib\site-packages\django\db\models\query.py", line 1511, in _filter_or_exclude
    clone._filter_or_exclude_inplace(negate, args, kwargs)
  File "D:\DMS-GOA\vvenv\Lib\site-packages\django\db\models\query.py", line 1518, in _filter_or_exclude_inplace
    self._query.add_q(Q(*args, **kwargs))
  File "D:\DMS-GOA\vvenv\Lib\site-packages\django\db\models\sql\query.py", line 1646, in add_q
    clause, _ = self._add_q(q_object, can_reuse)
                ^^^^^^^^^^^^^^^^^^^^^^^^^^^^^^^^
  File "D:\DMS-GOA\vvenv\Lib\site-packages\django\db\models\sql\query.py", line 1678, in _add_q
    child_clause, needed_inner = self.build_filter(
                                 ^^^^^^^^^^^^^^^^^^
  File "D:\DMS-GOA\vvenv\Lib\site-packages\django\db\models\sql\query.py", line 1588, in build_filter
    condition = self.build_lookup(lookups, col, value)
                ^^^^^^^^^^^^^^^^^^^^^^^^^^^^^^^^^^^^^^
  File "D:\DMS-GOA\vvenv\Lib\site-packages\django\db\models\sql\query.py", line 1415, in build_lookup
    lookup = lookup_class(lhs, rhs)
             ^^^^^^^^^^^^^^^^^^^^^^
  File "D:\DMS-GOA\vvenv\Lib\site-packages\django\db\models\lookups.py", line 38, in __init__
    self.rhs = self.get_prep_lookup()
               ^^^^^^^^^^^^^^^^^^^^^^
  File "D:\DMS-GOA\vvenv\Lib\site-packages\django\db\models\fields\related_lookups.py", line 67, in get_prep_lookup
    self.rhs = [target_field.get_prep_value(v) for v in self.rhs]
                ^^^^^^^^^^^^^^^^^^^^^^^^^^^^^^
  File "D:\DMS-GOA\vvenv\Lib\site-packages\django\db\models\fields\__init__.py", line 2130, in get_prep_value
    raise e.__class__(
TypeError: Field 'responder_id' expected a number but got <django.db.models.sql.query.Query object at 0x0000020276F14980>.
ERROR 2025-08-25 15:19:20,170 basehttp "GET /admin_web/get_responder_list/5/ HTTP/1.1" 500 160282
WARNING 2025-08-25 15:19:20,367 log Not Found: /favicon.ico
WARNING 2025-08-25 15:19:20,367 basehttp "GET /favicon.ico HTTP/1.1" 404 2833
WARNING 2025-08-25 15:19:56,239 log Not Found: /.well-known/appspecific/com.chrome.devtools.json
WARNING 2025-08-25 15:19:56,240 basehttp "GET /.well-known/appspecific/com.chrome.devtools.json HTTP/1.1" 404 2944
ERROR 2025-08-25 15:22:33,879 log Internal Server Error: /admin_web/get_responder_list/5/
Traceback (most recent call last):
  File "D:\DMS-GOA\vvenv\Lib\site-packages\django\core\handlers\exception.py", line 55, in inner
    response = get_response(request)
               ^^^^^^^^^^^^^^^^^^^^^
  File "D:\DMS-GOA\vvenv\Lib\site-packages\django\core\handlers\base.py", line 197, in _get_response
    response = wrapped_callback(request, *callback_args, **callback_kwargs)
               ^^^^^^^^^^^^^^^^^^^^^^^^^^^^^^^^^^^^^^^^^^^^^^^^^^^^^^^^^^^^
  File "D:\DMS-GOA\vvenv\Lib\site-packages\django\views\decorators\csrf.py", line 65, in _view_wrapper
    return view_func(request, *args, **kwargs)
           ^^^^^^^^^^^^^^^^^^^^^^^^^^^^^^^^^^^
  File "D:\DMS-GOA\vvenv\Lib\site-packages\django\views\generic\base.py", line 105, in view
    return self.dispatch(request, *args, **kwargs)
           ^^^^^^^^^^^^^^^^^^^^^^^^^^^^^^^^^^^^^^^
  File "D:\DMS-GOA\vvenv\Lib\site-packages\rest_framework\views.py", line 515, in dispatch
    response = self.handle_exception(exc)
               ^^^^^^^^^^^^^^^^^^^^^^^^^^
  File "D:\DMS-GOA\vvenv\Lib\site-packages\rest_framework\views.py", line 475, in handle_exception
    self.raise_uncaught_exception(exc)
  File "D:\DMS-GOA\vvenv\Lib\site-packages\rest_framework\views.py", line 486, in raise_uncaught_exception
    raise exc
  File "D:\DMS-GOA\vvenv\Lib\site-packages\rest_framework\views.py", line 512, in dispatch
    response = handler(request, *args, **kwargs)
               ^^^^^^^^^^^^^^^^^^^^^^^^^^^^^^^^^
  File "D:\DMS-GOA\DMS_goa\admin_web\views.py", line 1660, in get
    rm_cl_ve = in_cl_dt.filter(vehicle_no__in=inc_ws_ve.veh_id.values_list('vehicle_no', flat=True)).values_list('vehicle_no', flat=True)
                                              ^^^^^^^^^^^^^^^^
AttributeError: 'QuerySet' object has no attribute 'veh_id'
ERROR 2025-08-25 15:22:33,886 basehttp "GET /admin_web/get_responder_list/5/ HTTP/1.1" 500 99454
ERROR 2025-08-25 15:22:36,665 log Internal Server Error: /admin_web/get_responder_list/5/
Traceback (most recent call last):
  File "D:\DMS-GOA\vvenv\Lib\site-packages\django\core\handlers\exception.py", line 55, in inner
    response = get_response(request)
               ^^^^^^^^^^^^^^^^^^^^^
  File "D:\DMS-GOA\vvenv\Lib\site-packages\django\core\handlers\base.py", line 197, in _get_response
    response = wrapped_callback(request, *callback_args, **callback_kwargs)
               ^^^^^^^^^^^^^^^^^^^^^^^^^^^^^^^^^^^^^^^^^^^^^^^^^^^^^^^^^^^^
  File "D:\DMS-GOA\vvenv\Lib\site-packages\django\views\decorators\csrf.py", line 65, in _view_wrapper
    return view_func(request, *args, **kwargs)
           ^^^^^^^^^^^^^^^^^^^^^^^^^^^^^^^^^^^
  File "D:\DMS-GOA\vvenv\Lib\site-packages\django\views\generic\base.py", line 105, in view
    return self.dispatch(request, *args, **kwargs)
           ^^^^^^^^^^^^^^^^^^^^^^^^^^^^^^^^^^^^^^^
  File "D:\DMS-GOA\vvenv\Lib\site-packages\rest_framework\views.py", line 515, in dispatch
    response = self.handle_exception(exc)
               ^^^^^^^^^^^^^^^^^^^^^^^^^^
  File "D:\DMS-GOA\vvenv\Lib\site-packages\rest_framework\views.py", line 475, in handle_exception
    self.raise_uncaught_exception(exc)
  File "D:\DMS-GOA\vvenv\Lib\site-packages\rest_framework\views.py", line 486, in raise_uncaught_exception
    raise exc
  File "D:\DMS-GOA\vvenv\Lib\site-packages\rest_framework\views.py", line 512, in dispatch
    response = handler(request, *args, **kwargs)
               ^^^^^^^^^^^^^^^^^^^^^^^^^^^^^^^^^
  File "D:\DMS-GOA\DMS_goa\admin_web\views.py", line 1660, in get
    rm_cl_ve = in_cl_dt.filter(vehicle_no__in=inc_ws_ve.veh_id.values_list('vehicle_no', flat=True)).values_list('vehicle_no', flat=True)
                                              ^^^^^^^^^^^^^^^^
AttributeError: 'QuerySet' object has no attribute 'veh_id'
ERROR 2025-08-25 15:22:36,669 basehttp "GET /admin_web/get_responder_list/5/ HTTP/1.1" 500 99317
ERROR 2025-08-25 15:28:57,199 log Internal Server Error: /admin_web/get_responder_list/5/
Traceback (most recent call last):
  File "D:\DMS-GOA\vvenv\Lib\site-packages\django\core\handlers\exception.py", line 55, in inner
    response = get_response(request)
               ^^^^^^^^^^^^^^^^^^^^^
  File "D:\DMS-GOA\vvenv\Lib\site-packages\django\core\handlers\base.py", line 197, in _get_response
    response = wrapped_callback(request, *callback_args, **callback_kwargs)
               ^^^^^^^^^^^^^^^^^^^^^^^^^^^^^^^^^^^^^^^^^^^^^^^^^^^^^^^^^^^^
  File "D:\DMS-GOA\vvenv\Lib\site-packages\django\views\decorators\csrf.py", line 65, in _view_wrapper
    return view_func(request, *args, **kwargs)
           ^^^^^^^^^^^^^^^^^^^^^^^^^^^^^^^^^^^
  File "D:\DMS-GOA\vvenv\Lib\site-packages\django\views\generic\base.py", line 105, in view
    return self.dispatch(request, *args, **kwargs)
           ^^^^^^^^^^^^^^^^^^^^^^^^^^^^^^^^^^^^^^^
  File "D:\DMS-GOA\vvenv\Lib\site-packages\rest_framework\views.py", line 515, in dispatch
    response = self.handle_exception(exc)
               ^^^^^^^^^^^^^^^^^^^^^^^^^^
  File "D:\DMS-GOA\vvenv\Lib\site-packages\rest_framework\views.py", line 475, in handle_exception
    self.raise_uncaught_exception(exc)
  File "D:\DMS-GOA\vvenv\Lib\site-packages\rest_framework\views.py", line 486, in raise_uncaught_exception
    raise exc
  File "D:\DMS-GOA\vvenv\Lib\site-packages\rest_framework\views.py", line 512, in dispatch
    response = handler(request, *args, **kwargs)
               ^^^^^^^^^^^^^^^^^^^^^^^^^^^^^^^^^
  File "D:\DMS-GOA\DMS_goa\admin_web\views.py", line 1660, in get
    rm_cl_ve = in_cl_dt.filter(vehicle_no__in=inc_ws_ve.veh_id.values_list('vehicle_no', flat=True)).values_list('vehicle_no', flat=True)
                                              ^^^^^^^^^^^^^^^^
AttributeError: 'QuerySet' object has no attribute 'veh_id'
ERROR 2025-08-25 15:28:57,208 basehttp "GET /admin_web/get_responder_list/5/ HTTP/1.1" 500 99317
ERROR 2025-08-25 15:56:31,262 log Internal Server Error: /admin_web/get_responder_list/5/
Traceback (most recent call last):
  File "D:\DMS-GOA\vvenv\Lib\site-packages\django\core\handlers\exception.py", line 55, in inner
    response = get_response(request)
               ^^^^^^^^^^^^^^^^^^^^^
  File "D:\DMS-GOA\vvenv\Lib\site-packages\django\core\handlers\base.py", line 197, in _get_response
    response = wrapped_callback(request, *callback_args, **callback_kwargs)
               ^^^^^^^^^^^^^^^^^^^^^^^^^^^^^^^^^^^^^^^^^^^^^^^^^^^^^^^^^^^^
  File "D:\DMS-GOA\vvenv\Lib\site-packages\django\views\decorators\csrf.py", line 65, in _view_wrapper
    return view_func(request, *args, **kwargs)
           ^^^^^^^^^^^^^^^^^^^^^^^^^^^^^^^^^^^
  File "D:\DMS-GOA\vvenv\Lib\site-packages\django\views\generic\base.py", line 105, in view
    return self.dispatch(request, *args, **kwargs)
           ^^^^^^^^^^^^^^^^^^^^^^^^^^^^^^^^^^^^^^^
  File "D:\DMS-GOA\vvenv\Lib\site-packages\rest_framework\views.py", line 515, in dispatch
    response = self.handle_exception(exc)
               ^^^^^^^^^^^^^^^^^^^^^^^^^^
  File "D:\DMS-GOA\vvenv\Lib\site-packages\rest_framework\views.py", line 475, in handle_exception
    self.raise_uncaught_exception(exc)
  File "D:\DMS-GOA\vvenv\Lib\site-packages\rest_framework\views.py", line 486, in raise_uncaught_exception
    raise exc
  File "D:\DMS-GOA\vvenv\Lib\site-packages\rest_framework\views.py", line 512, in dispatch
    response = handler(request, *args, **kwargs)
               ^^^^^^^^^^^^^^^^^^^^^^^^^^^^^^^^^
  File "D:\DMS-GOA\DMS_goa\admin_web\views.py", line 1661, in get
    rm_cl_ve = in_cl_dt.filter(vehicle_no__in=inc_ws_ve.veh_id.values_list('vehicle_no', flat=True)).values_list('vehicle_no', flat=True)
                                              ^^^^^^^^^^^^^^^^
AttributeError: 'QuerySet' object has no attribute 'veh_id'
ERROR 2025-08-25 15:56:31,269 basehttp "GET /admin_web/get_responder_list/5/ HTTP/1.1" 500 99578
WARNING 2025-08-25 15:56:31,427 log Not Found: /favicon.ico
WARNING 2025-08-25 15:56:31,428 basehttp "GET /favicon.ico HTTP/1.1" 404 2833
ERROR 2025-08-25 16:04:09,383 log Internal Server Error: /admin_web/get_responder_list/10/
Traceback (most recent call last):
  File "D:\DMS-GOA\vvenv\Lib\site-packages\django\core\handlers\exception.py", line 55, in inner
    response = get_response(request)
               ^^^^^^^^^^^^^^^^^^^^^
  File "D:\DMS-GOA\vvenv\Lib\site-packages\django\core\handlers\base.py", line 197, in _get_response
    response = wrapped_callback(request, *callback_args, **callback_kwargs)
               ^^^^^^^^^^^^^^^^^^^^^^^^^^^^^^^^^^^^^^^^^^^^^^^^^^^^^^^^^^^^
  File "D:\DMS-GOA\vvenv\Lib\site-packages\django\views\decorators\csrf.py", line 65, in _view_wrapper
    return view_func(request, *args, **kwargs)
           ^^^^^^^^^^^^^^^^^^^^^^^^^^^^^^^^^^^
  File "D:\DMS-GOA\vvenv\Lib\site-packages\django\views\generic\base.py", line 105, in view
    return self.dispatch(request, *args, **kwargs)
           ^^^^^^^^^^^^^^^^^^^^^^^^^^^^^^^^^^^^^^^
  File "D:\DMS-GOA\vvenv\Lib\site-packages\rest_framework\views.py", line 515, in dispatch
    response = self.handle_exception(exc)
               ^^^^^^^^^^^^^^^^^^^^^^^^^^
  File "D:\DMS-GOA\vvenv\Lib\site-packages\rest_framework\views.py", line 475, in handle_exception
    self.raise_uncaught_exception(exc)
  File "D:\DMS-GOA\vvenv\Lib\site-packages\rest_framework\views.py", line 486, in raise_uncaught_exception
    raise exc
  File "D:\DMS-GOA\vvenv\Lib\site-packages\rest_framework\views.py", line 512, in dispatch
    response = handler(request, *args, **kwargs)
               ^^^^^^^^^^^^^^^^^^^^^^^^^^^^^^^^^
  File "D:\DMS-GOA\DMS_goa\admin_web\views.py", line 1661, in get
    rm_cl_ve = in_cl_dt.filter(vehicle_no__in=inc_ws_ve.veh_id).values_list('vehicle_no', flat=True)
                                              ^^^^^^^^^^^^^^^^
AttributeError: 'QuerySet' object has no attribute 'veh_id'
ERROR 2025-08-25 16:04:09,390 basehttp "GET /admin_web/get_responder_list/10/ HTTP/1.1" 500 99250
ERROR 2025-08-25 16:10:16,836 log Internal Server Error: /admin_web/get_responder_list/10/
Traceback (most recent call last):
  File "D:\DMS-GOA\vvenv\Lib\site-packages\django\core\handlers\exception.py", line 55, in inner
    response = get_response(request)
               ^^^^^^^^^^^^^^^^^^^^^
  File "D:\DMS-GOA\vvenv\Lib\site-packages\django\core\handlers\base.py", line 197, in _get_response
    response = wrapped_callback(request, *callback_args, **callback_kwargs)
               ^^^^^^^^^^^^^^^^^^^^^^^^^^^^^^^^^^^^^^^^^^^^^^^^^^^^^^^^^^^^
  File "D:\DMS-GOA\vvenv\Lib\site-packages\django\views\decorators\csrf.py", line 65, in _view_wrapper
    return view_func(request, *args, **kwargs)
           ^^^^^^^^^^^^^^^^^^^^^^^^^^^^^^^^^^^
  File "D:\DMS-GOA\vvenv\Lib\site-packages\django\views\generic\base.py", line 105, in view
    return self.dispatch(request, *args, **kwargs)
           ^^^^^^^^^^^^^^^^^^^^^^^^^^^^^^^^^^^^^^^
  File "D:\DMS-GOA\vvenv\Lib\site-packages\rest_framework\views.py", line 515, in dispatch
    response = self.handle_exception(exc)
               ^^^^^^^^^^^^^^^^^^^^^^^^^^
  File "D:\DMS-GOA\vvenv\Lib\site-packages\rest_framework\views.py", line 475, in handle_exception
    self.raise_uncaught_exception(exc)
  File "D:\DMS-GOA\vvenv\Lib\site-packages\rest_framework\views.py", line 486, in raise_uncaught_exception
    raise exc
  File "D:\DMS-GOA\vvenv\Lib\site-packages\rest_framework\views.py", line 512, in dispatch
    response = handler(request, *args, **kwargs)
               ^^^^^^^^^^^^^^^^^^^^^^^^^^^^^^^^^
  File "D:\DMS-GOA\DMS_goa\admin_web\views.py", line 1661, in get
    rm_cl_ve = in_cl_dt.filter(vehicle_no__in=inc_ws_ve.veh_id).values_list('vehicle_no', flat=True)
                                              ^^^^^^^^^^^^^^^^
AttributeError: 'QuerySet' object has no attribute 'veh_id'
ERROR 2025-08-25 16:10:16,840 basehttp "GET /admin_web/get_responder_list/10/ HTTP/1.1" 500 99596
ERROR 2025-08-25 16:12:17,300 log Internal Server Error: /admin_web/get_responder_list/10/
Traceback (most recent call last):
  File "D:\DMS-GOA\vvenv\Lib\site-packages\django\core\handlers\exception.py", line 55, in inner
    response = get_response(request)
               ^^^^^^^^^^^^^^^^^^^^^
  File "D:\DMS-GOA\vvenv\Lib\site-packages\django\core\handlers\base.py", line 197, in _get_response
    response = wrapped_callback(request, *callback_args, **callback_kwargs)
               ^^^^^^^^^^^^^^^^^^^^^^^^^^^^^^^^^^^^^^^^^^^^^^^^^^^^^^^^^^^^
  File "D:\DMS-GOA\vvenv\Lib\site-packages\django\views\decorators\csrf.py", line 65, in _view_wrapper
    return view_func(request, *args, **kwargs)
           ^^^^^^^^^^^^^^^^^^^^^^^^^^^^^^^^^^^
  File "D:\DMS-GOA\vvenv\Lib\site-packages\django\views\generic\base.py", line 105, in view
    return self.dispatch(request, *args, **kwargs)
           ^^^^^^^^^^^^^^^^^^^^^^^^^^^^^^^^^^^^^^^
  File "D:\DMS-GOA\vvenv\Lib\site-packages\rest_framework\views.py", line 515, in dispatch
    response = self.handle_exception(exc)
               ^^^^^^^^^^^^^^^^^^^^^^^^^^
  File "D:\DMS-GOA\vvenv\Lib\site-packages\rest_framework\views.py", line 475, in handle_exception
    self.raise_uncaught_exception(exc)
  File "D:\DMS-GOA\vvenv\Lib\site-packages\rest_framework\views.py", line 486, in raise_uncaught_exception
    raise exc
  File "D:\DMS-GOA\vvenv\Lib\site-packages\rest_framework\views.py", line 512, in dispatch
    response = handler(request, *args, **kwargs)
               ^^^^^^^^^^^^^^^^^^^^^^^^^^^^^^^^^
  File "D:\DMS-GOA\DMS_goa\admin_web\views.py", line 1661, in get
    if inc_ws_ve.veh_id:
       ^^^^^^^^^^^^^^^^
AttributeError: 'QuerySet' object has no attribute 'veh_id'
ERROR 2025-08-25 16:12:17,304 basehttp "GET /admin_web/get_responder_list/10/ HTTP/1.1" 500 99474
ERROR 2025-08-25 16:12:20,352 log Internal Server Error: /admin_web/get_responder_list/10/
Traceback (most recent call last):
  File "D:\DMS-GOA\vvenv\Lib\site-packages\django\core\handlers\exception.py", line 55, in inner
    response = get_response(request)
               ^^^^^^^^^^^^^^^^^^^^^
  File "D:\DMS-GOA\vvenv\Lib\site-packages\django\core\handlers\base.py", line 197, in _get_response
    response = wrapped_callback(request, *callback_args, **callback_kwargs)
               ^^^^^^^^^^^^^^^^^^^^^^^^^^^^^^^^^^^^^^^^^^^^^^^^^^^^^^^^^^^^
  File "D:\DMS-GOA\vvenv\Lib\site-packages\django\views\decorators\csrf.py", line 65, in _view_wrapper
    return view_func(request, *args, **kwargs)
           ^^^^^^^^^^^^^^^^^^^^^^^^^^^^^^^^^^^
  File "D:\DMS-GOA\vvenv\Lib\site-packages\django\views\generic\base.py", line 105, in view
    return self.dispatch(request, *args, **kwargs)
           ^^^^^^^^^^^^^^^^^^^^^^^^^^^^^^^^^^^^^^^
  File "D:\DMS-GOA\vvenv\Lib\site-packages\rest_framework\views.py", line 515, in dispatch
    response = self.handle_exception(exc)
               ^^^^^^^^^^^^^^^^^^^^^^^^^^
  File "D:\DMS-GOA\vvenv\Lib\site-packages\rest_framework\views.py", line 475, in handle_exception
    self.raise_uncaught_exception(exc)
  File "D:\DMS-GOA\vvenv\Lib\site-packages\rest_framework\views.py", line 486, in raise_uncaught_exception
    raise exc
  File "D:\DMS-GOA\vvenv\Lib\site-packages\rest_framework\views.py", line 512, in dispatch
    response = handler(request, *args, **kwargs)
               ^^^^^^^^^^^^^^^^^^^^^^^^^^^^^^^^^
  File "D:\DMS-GOA\DMS_goa\admin_web\views.py", line 1661, in get
    if inc_ws_ve.veh_id:
       ^^^^^^^^^^^^^^^^
AttributeError: 'QuerySet' object has no attribute 'veh_id'
ERROR 2025-08-25 16:12:20,355 basehttp "GET /admin_web/get_responder_list/10/ HTTP/1.1" 500 99474
ERROR 2025-08-25 16:12:43,707 log Internal Server Error: /admin_web/get_responder_list/10/
Traceback (most recent call last):
  File "D:\DMS-GOA\vvenv\Lib\site-packages\django\db\backends\utils.py", line 105, in _execute
    return self.cursor.execute(sql, params)
           ^^^^^^^^^^^^^^^^^^^^^^^^^^^^^^^^
psycopg2.errors.UndefinedFunction: operator does not exist: integer = character varying
LINE 1: ...ical" ON ("DMS_MDT_incident_vehicles"."veh_id_id" = "DMS_MDT...
                                                             ^
HINT:  No operator matches the given name and argument types. You might need to add explicit type casts.


The above exception was the direct cause of the following exception:

Traceback (most recent call last):
  File "D:\DMS-GOA\vvenv\Lib\site-packages\django\core\handlers\exception.py", line 55, in inner
    response = get_response(request)
               ^^^^^^^^^^^^^^^^^^^^^
  File "D:\DMS-GOA\vvenv\Lib\site-packages\django\core\handlers\base.py", line 197, in _get_response
    response = wrapped_callback(request, *callback_args, **callback_kwargs)
               ^^^^^^^^^^^^^^^^^^^^^^^^^^^^^^^^^^^^^^^^^^^^^^^^^^^^^^^^^^^^
  File "D:\DMS-GOA\vvenv\Lib\site-packages\django\views\decorators\csrf.py", line 65, in _view_wrapper
    return view_func(request, *args, **kwargs)
           ^^^^^^^^^^^^^^^^^^^^^^^^^^^^^^^^^^^
  File "D:\DMS-GOA\vvenv\Lib\site-packages\django\views\generic\base.py", line 105, in view
    return self.dispatch(request, *args, **kwargs)
           ^^^^^^^^^^^^^^^^^^^^^^^^^^^^^^^^^^^^^^^
  File "D:\DMS-GOA\vvenv\Lib\site-packages\rest_framework\views.py", line 515, in dispatch
    response = self.handle_exception(exc)
               ^^^^^^^^^^^^^^^^^^^^^^^^^^
  File "D:\DMS-GOA\vvenv\Lib\site-packages\rest_framework\views.py", line 475, in handle_exception
    self.raise_uncaught_exception(exc)
  File "D:\DMS-GOA\vvenv\Lib\site-packages\rest_framework\views.py", line 486, in raise_uncaught_exception
    raise exc
  File "D:\DMS-GOA\vvenv\Lib\site-packages\rest_framework\views.py", line 512, in dispatch
    response = handler(request, *args, **kwargs)
               ^^^^^^^^^^^^^^^^^^^^^^^^^^^^^^^^^
  File "D:\DMS-GOA\DMS_goa\admin_web\views.py", line 1661, in get
    print(inc_ws_ve)
  File "D:\DMS-GOA\vvenv\Lib\site-packages\django\db\models\query.py", line 360, in __repr__
    data = list(self[: REPR_OUTPUT_SIZE + 1])
           ^^^^^^^^^^^^^^^^^^^^^^^^^^^^^^^^^^
  File "D:\DMS-GOA\vvenv\Lib\site-packages\django\db\models\query.py", line 384, in __iter__
    self._fetch_all()
  File "D:\DMS-GOA\vvenv\Lib\site-packages\django\db\models\query.py", line 1949, in _fetch_all
    self._result_cache = list(self._iterable_class(self))
                         ^^^^^^^^^^^^^^^^^^^^^^^^^^^^^^^^
  File "D:\DMS-GOA\vvenv\Lib\site-packages\django\db\models\query.py", line 91, in __iter__
    results = compiler.execute_sql(
              ^^^^^^^^^^^^^^^^^^^^^
  File "D:\DMS-GOA\vvenv\Lib\site-packages\django\db\models\sql\compiler.py", line 1623, in execute_sql
    cursor.execute(sql, params)
  File "D:\DMS-GOA\vvenv\Lib\site-packages\django\db\backends\utils.py", line 122, in execute
    return super().execute(sql, params)
           ^^^^^^^^^^^^^^^^^^^^^^^^^^^^
  File "D:\DMS-GOA\vvenv\Lib\site-packages\django\db\backends\utils.py", line 79, in execute
    return self._execute_with_wrappers(
           ^^^^^^^^^^^^^^^^^^^^^^^^^^^^
  File "D:\DMS-GOA\vvenv\Lib\site-packages\django\db\backends\utils.py", line 92, in _execute_with_wrappers
    return executor(sql, params, many, context)
           ^^^^^^^^^^^^^^^^^^^^^^^^^^^^^^^^^^^^
  File "D:\DMS-GOA\vvenv\Lib\site-packages\django\db\backends\utils.py", line 100, in _execute
    with self.db.wrap_database_errors:
         ^^^^^^^^^^^^^^^^^^^^^^^^^^^^
  File "D:\DMS-GOA\vvenv\Lib\site-packages\django\db\utils.py", line 91, in __exit__
    raise dj_exc_value.with_traceback(traceback) from exc_value
  File "D:\DMS-GOA\vvenv\Lib\site-packages\django\db\backends\utils.py", line 105, in _execute
    return self.cursor.execute(sql, params)
           ^^^^^^^^^^^^^^^^^^^^^^^^^^^^^^^^
django.db.utils.ProgrammingError: operator does not exist: integer = character varying
LINE 1: ...ical" ON ("DMS_MDT_incident_vehicles"."veh_id_id" = "DMS_MDT...
                                                             ^
HINT:  No operator matches the given name and argument types. You might need to add explicit type casts.

ERROR 2025-08-25 16:12:43,713 basehttp "GET /admin_web/get_responder_list/10/ HTTP/1.1" 500 164729
ERROR 2025-08-25 16:12:52,451 log Internal Server Error: /admin_web/get_responder_list/10/
Traceback (most recent call last):
  File "D:\DMS-GOA\vvenv\Lib\site-packages\django\db\backends\utils.py", line 105, in _execute
    return self.cursor.execute(sql, params)
           ^^^^^^^^^^^^^^^^^^^^^^^^^^^^^^^^
psycopg2.errors.UndefinedFunction: operator does not exist: integer = character varying
LINE 1: ...ical" ON ("DMS_MDT_incident_vehicles"."veh_id_id" = "DMS_MDT...
                                                             ^
HINT:  No operator matches the given name and argument types. You might need to add explicit type casts.


The above exception was the direct cause of the following exception:

Traceback (most recent call last):
  File "D:\DMS-GOA\vvenv\Lib\site-packages\django\core\handlers\exception.py", line 55, in inner
    response = get_response(request)
               ^^^^^^^^^^^^^^^^^^^^^
  File "D:\DMS-GOA\vvenv\Lib\site-packages\django\core\handlers\base.py", line 197, in _get_response
    response = wrapped_callback(request, *callback_args, **callback_kwargs)
               ^^^^^^^^^^^^^^^^^^^^^^^^^^^^^^^^^^^^^^^^^^^^^^^^^^^^^^^^^^^^
  File "D:\DMS-GOA\vvenv\Lib\site-packages\django\views\decorators\csrf.py", line 65, in _view_wrapper
    return view_func(request, *args, **kwargs)
           ^^^^^^^^^^^^^^^^^^^^^^^^^^^^^^^^^^^
  File "D:\DMS-GOA\vvenv\Lib\site-packages\django\views\generic\base.py", line 105, in view
    return self.dispatch(request, *args, **kwargs)
           ^^^^^^^^^^^^^^^^^^^^^^^^^^^^^^^^^^^^^^^
  File "D:\DMS-GOA\vvenv\Lib\site-packages\rest_framework\views.py", line 515, in dispatch
    response = self.handle_exception(exc)
               ^^^^^^^^^^^^^^^^^^^^^^^^^^
  File "D:\DMS-GOA\vvenv\Lib\site-packages\rest_framework\views.py", line 475, in handle_exception
    self.raise_uncaught_exception(exc)
  File "D:\DMS-GOA\vvenv\Lib\site-packages\rest_framework\views.py", line 486, in raise_uncaught_exception
    raise exc
  File "D:\DMS-GOA\vvenv\Lib\site-packages\rest_framework\views.py", line 512, in dispatch
    response = handler(request, *args, **kwargs)
               ^^^^^^^^^^^^^^^^^^^^^^^^^^^^^^^^^
  File "D:\DMS-GOA\DMS_goa\admin_web\views.py", line 1661, in get
    print(inc_ws_ve)
  File "D:\DMS-GOA\vvenv\Lib\site-packages\django\db\models\query.py", line 360, in __repr__
    data = list(self[: REPR_OUTPUT_SIZE + 1])
           ^^^^^^^^^^^^^^^^^^^^^^^^^^^^^^^^^^
  File "D:\DMS-GOA\vvenv\Lib\site-packages\django\db\models\query.py", line 384, in __iter__
    self._fetch_all()
  File "D:\DMS-GOA\vvenv\Lib\site-packages\django\db\models\query.py", line 1949, in _fetch_all
    self._result_cache = list(self._iterable_class(self))
                         ^^^^^^^^^^^^^^^^^^^^^^^^^^^^^^^^
  File "D:\DMS-GOA\vvenv\Lib\site-packages\django\db\models\query.py", line 91, in __iter__
    results = compiler.execute_sql(
              ^^^^^^^^^^^^^^^^^^^^^
  File "D:\DMS-GOA\vvenv\Lib\site-packages\django\db\models\sql\compiler.py", line 1623, in execute_sql
    cursor.execute(sql, params)
  File "D:\DMS-GOA\vvenv\Lib\site-packages\django\db\backends\utils.py", line 122, in execute
    return super().execute(sql, params)
           ^^^^^^^^^^^^^^^^^^^^^^^^^^^^
  File "D:\DMS-GOA\vvenv\Lib\site-packages\django\db\backends\utils.py", line 79, in execute
    return self._execute_with_wrappers(
           ^^^^^^^^^^^^^^^^^^^^^^^^^^^^
  File "D:\DMS-GOA\vvenv\Lib\site-packages\django\db\backends\utils.py", line 92, in _execute_with_wrappers
    return executor(sql, params, many, context)
           ^^^^^^^^^^^^^^^^^^^^^^^^^^^^^^^^^^^^
  File "D:\DMS-GOA\vvenv\Lib\site-packages\django\db\backends\utils.py", line 100, in _execute
    with self.db.wrap_database_errors:
         ^^^^^^^^^^^^^^^^^^^^^^^^^^^^
  File "D:\DMS-GOA\vvenv\Lib\site-packages\django\db\utils.py", line 91, in __exit__
    raise dj_exc_value.with_traceback(traceback) from exc_value
  File "D:\DMS-GOA\vvenv\Lib\site-packages\django\db\backends\utils.py", line 105, in _execute
    return self.cursor.execute(sql, params)
           ^^^^^^^^^^^^^^^^^^^^^^^^^^^^^^^^
django.db.utils.ProgrammingError: operator does not exist: integer = character varying
LINE 1: ...ical" ON ("DMS_MDT_incident_vehicles"."veh_id_id" = "DMS_MDT...
                                                             ^
HINT:  No operator matches the given name and argument types. You might need to add explicit type casts.

ERROR 2025-08-25 16:12:52,453 basehttp "GET /admin_web/get_responder_list/10/ HTTP/1.1" 500 164729
ERROR 2025-08-25 16:19:07,480 log Internal Server Error: /admin_web/get_responder_list/10/
Traceback (most recent call last):
  File "D:\DMS-GOA\vvenv\Lib\site-packages\django\core\handlers\exception.py", line 55, in inner
    response = get_response(request)
               ^^^^^^^^^^^^^^^^^^^^^
  File "D:\DMS-GOA\vvenv\Lib\site-packages\django\core\handlers\base.py", line 197, in _get_response
    response = wrapped_callback(request, *callback_args, **callback_kwargs)
               ^^^^^^^^^^^^^^^^^^^^^^^^^^^^^^^^^^^^^^^^^^^^^^^^^^^^^^^^^^^^
  File "D:\DMS-GOA\vvenv\Lib\site-packages\django\views\decorators\csrf.py", line 65, in _view_wrapper
    return view_func(request, *args, **kwargs)
           ^^^^^^^^^^^^^^^^^^^^^^^^^^^^^^^^^^^
  File "D:\DMS-GOA\vvenv\Lib\site-packages\django\views\generic\base.py", line 105, in view
    return self.dispatch(request, *args, **kwargs)
           ^^^^^^^^^^^^^^^^^^^^^^^^^^^^^^^^^^^^^^^
  File "D:\DMS-GOA\vvenv\Lib\site-packages\rest_framework\views.py", line 515, in dispatch
    response = self.handle_exception(exc)
               ^^^^^^^^^^^^^^^^^^^^^^^^^^
  File "D:\DMS-GOA\vvenv\Lib\site-packages\rest_framework\views.py", line 475, in handle_exception
    self.raise_uncaught_exception(exc)
  File "D:\DMS-GOA\vvenv\Lib\site-packages\rest_framework\views.py", line 486, in raise_uncaught_exception
    raise exc
  File "D:\DMS-GOA\vvenv\Lib\site-packages\rest_framework\views.py", line 512, in dispatch
    response = handler(request, *args, **kwargs)
               ^^^^^^^^^^^^^^^^^^^^^^^^^^^^^^^^^
  File "D:\DMS-GOA\DMS_goa\admin_web\views.py", line 1662, in get
    for j in list(set(i.alert_type_id)):
                  ^^^^^^^^^^^^^^^^^^^^
TypeError: 'ManyRelatedManager' object is not iterable
ERROR 2025-08-25 16:19:07,486 basehttp "GET /admin_web/get_responder_list/10/ HTTP/1.1" 500 98411
ERROR 2025-08-25 16:20:05,673 log Internal Server Error: /admin_web/get_responder_list/10/
Traceback (most recent call last):
  File "D:\DMS-GOA\vvenv\Lib\site-packages\django\core\handlers\exception.py", line 55, in inner
    response = get_response(request)
               ^^^^^^^^^^^^^^^^^^^^^
  File "D:\DMS-GOA\vvenv\Lib\site-packages\django\core\handlers\base.py", line 197, in _get_response
    response = wrapped_callback(request, *callback_args, **callback_kwargs)
               ^^^^^^^^^^^^^^^^^^^^^^^^^^^^^^^^^^^^^^^^^^^^^^^^^^^^^^^^^^^^
  File "D:\DMS-GOA\vvenv\Lib\site-packages\django\views\decorators\csrf.py", line 65, in _view_wrapper
    return view_func(request, *args, **kwargs)
           ^^^^^^^^^^^^^^^^^^^^^^^^^^^^^^^^^^^
  File "D:\DMS-GOA\vvenv\Lib\site-packages\django\views\generic\base.py", line 105, in view
    return self.dispatch(request, *args, **kwargs)
           ^^^^^^^^^^^^^^^^^^^^^^^^^^^^^^^^^^^^^^^
  File "D:\DMS-GOA\vvenv\Lib\site-packages\rest_framework\views.py", line 515, in dispatch
    response = self.handle_exception(exc)
               ^^^^^^^^^^^^^^^^^^^^^^^^^^
  File "D:\DMS-GOA\vvenv\Lib\site-packages\rest_framework\views.py", line 475, in handle_exception
    self.raise_uncaught_exception(exc)
  File "D:\DMS-GOA\vvenv\Lib\site-packages\rest_framework\views.py", line 486, in raise_uncaught_exception
    raise exc
  File "D:\DMS-GOA\vvenv\Lib\site-packages\rest_framework\views.py", line 512, in dispatch
    response = handler(request, *args, **kwargs)
               ^^^^^^^^^^^^^^^^^^^^^^^^^^^^^^^^^
  File "D:\DMS-GOA\DMS_goa\admin_web\views.py", line 1685, in get
    if inc_ws_ve.veh_id:
       ^^^^^^^^^^^^^^^^
AttributeError: 'QuerySet' object has no attribute 'veh_id'
ERROR 2025-08-25 16:20:05,677 basehttp "GET /admin_web/get_responder_list/10/ HTTP/1.1" 500 99255
WARNING 2025-08-25 17:47:48,119 log Not Found: /favicon.ico
WARNING 2025-08-25 17:47:48,120 basehttp "GET /favicon.ico HTTP/1.1" 404 2833
ERROR 2025-08-25 17:47:53,913 log Internal Server Error: /admin_web/get_responder_list/10/
Traceback (most recent call last):
  File "D:\DMS-GOA\vvenv\Lib\site-packages\django\core\handlers\exception.py", line 55, in inner
    response = get_response(request)
               ^^^^^^^^^^^^^^^^^^^^^
  File "D:\DMS-GOA\vvenv\Lib\site-packages\django\core\handlers\base.py", line 197, in _get_response
    response = wrapped_callback(request, *callback_args, **callback_kwargs)
               ^^^^^^^^^^^^^^^^^^^^^^^^^^^^^^^^^^^^^^^^^^^^^^^^^^^^^^^^^^^^
  File "D:\DMS-GOA\vvenv\Lib\site-packages\django\views\decorators\csrf.py", line 65, in _view_wrapper
    return view_func(request, *args, **kwargs)
           ^^^^^^^^^^^^^^^^^^^^^^^^^^^^^^^^^^^
  File "D:\DMS-GOA\vvenv\Lib\site-packages\django\views\generic\base.py", line 105, in view
    return self.dispatch(request, *args, **kwargs)
           ^^^^^^^^^^^^^^^^^^^^^^^^^^^^^^^^^^^^^^^
  File "D:\DMS-GOA\vvenv\Lib\site-packages\rest_framework\views.py", line 515, in dispatch
    response = self.handle_exception(exc)
               ^^^^^^^^^^^^^^^^^^^^^^^^^^
  File "D:\DMS-GOA\vvenv\Lib\site-packages\rest_framework\views.py", line 475, in handle_exception
    self.raise_uncaught_exception(exc)
  File "D:\DMS-GOA\vvenv\Lib\site-packages\rest_framework\views.py", line 486, in raise_uncaught_exception
    raise exc
  File "D:\DMS-GOA\vvenv\Lib\site-packages\rest_framework\views.py", line 512, in dispatch
    response = handler(request, *args, **kwargs)
               ^^^^^^^^^^^^^^^^^^^^^^^^^^^^^^^^^
  File "D:\DMS-GOA\DMS_goa\admin_web\views.py", line 1686, in get
    if inc_ws_ve.veh_id:
       ^^^^^^^^^^^^^^^^
AttributeError: 'QuerySet' object has no attribute 'veh_id'
ERROR 2025-08-25 17:47:53,918 basehttp "GET /admin_web/get_responder_list/10/ HTTP/1.1" 500 99061
ERROR 2025-08-25 17:47:57,771 log Internal Server Error: /admin_web/get_responder_list/10/
Traceback (most recent call last):
  File "D:\DMS-GOA\vvenv\Lib\site-packages\django\core\handlers\exception.py", line 55, in inner
    response = get_response(request)
               ^^^^^^^^^^^^^^^^^^^^^
  File "D:\DMS-GOA\vvenv\Lib\site-packages\django\core\handlers\base.py", line 197, in _get_response
    response = wrapped_callback(request, *callback_args, **callback_kwargs)
               ^^^^^^^^^^^^^^^^^^^^^^^^^^^^^^^^^^^^^^^^^^^^^^^^^^^^^^^^^^^^
  File "D:\DMS-GOA\vvenv\Lib\site-packages\django\views\decorators\csrf.py", line 65, in _view_wrapper
    return view_func(request, *args, **kwargs)
           ^^^^^^^^^^^^^^^^^^^^^^^^^^^^^^^^^^^
  File "D:\DMS-GOA\vvenv\Lib\site-packages\django\views\generic\base.py", line 105, in view
    return self.dispatch(request, *args, **kwargs)
           ^^^^^^^^^^^^^^^^^^^^^^^^^^^^^^^^^^^^^^^
  File "D:\DMS-GOA\vvenv\Lib\site-packages\rest_framework\views.py", line 515, in dispatch
    response = self.handle_exception(exc)
               ^^^^^^^^^^^^^^^^^^^^^^^^^^
  File "D:\DMS-GOA\vvenv\Lib\site-packages\rest_framework\views.py", line 475, in handle_exception
    self.raise_uncaught_exception(exc)
  File "D:\DMS-GOA\vvenv\Lib\site-packages\rest_framework\views.py", line 486, in raise_uncaught_exception
    raise exc
  File "D:\DMS-GOA\vvenv\Lib\site-packages\rest_framework\views.py", line 512, in dispatch
    response = handler(request, *args, **kwargs)
               ^^^^^^^^^^^^^^^^^^^^^^^^^^^^^^^^^
  File "D:\DMS-GOA\DMS_goa\admin_web\views.py", line 1686, in get
    if inc_ws_ve.veh_id:
       ^^^^^^^^^^^^^^^^
AttributeError: 'QuerySet' object has no attribute 'veh_id'
ERROR 2025-08-25 17:47:57,776 basehttp "GET /admin_web/get_responder_list/10/ HTTP/1.1" 500 99061
ERROR 2025-08-25 17:56:47,418 log Internal Server Error: /admin_web/get_responder_list/10/
Traceback (most recent call last):
  File "D:\DMS-GOA\vvenv\Lib\site-packages\django\core\handlers\exception.py", line 55, in inner
    response = get_response(request)
               ^^^^^^^^^^^^^^^^^^^^^
  File "D:\DMS-GOA\vvenv\Lib\site-packages\django\core\handlers\base.py", line 197, in _get_response
    response = wrapped_callback(request, *callback_args, **callback_kwargs)
               ^^^^^^^^^^^^^^^^^^^^^^^^^^^^^^^^^^^^^^^^^^^^^^^^^^^^^^^^^^^^
  File "D:\DMS-GOA\vvenv\Lib\site-packages\django\views\decorators\csrf.py", line 65, in _view_wrapper
    return view_func(request, *args, **kwargs)
           ^^^^^^^^^^^^^^^^^^^^^^^^^^^^^^^^^^^
  File "D:\DMS-GOA\vvenv\Lib\site-packages\django\views\generic\base.py", line 105, in view
    return self.dispatch(request, *args, **kwargs)
           ^^^^^^^^^^^^^^^^^^^^^^^^^^^^^^^^^^^^^^^
  File "D:\DMS-GOA\vvenv\Lib\site-packages\rest_framework\views.py", line 515, in dispatch
    response = self.handle_exception(exc)
               ^^^^^^^^^^^^^^^^^^^^^^^^^^
  File "D:\DMS-GOA\vvenv\Lib\site-packages\rest_framework\views.py", line 475, in handle_exception
    self.raise_uncaught_exception(exc)
  File "D:\DMS-GOA\vvenv\Lib\site-packages\rest_framework\views.py", line 486, in raise_uncaught_exception
    raise exc
  File "D:\DMS-GOA\vvenv\Lib\site-packages\rest_framework\views.py", line 512, in dispatch
    response = handler(request, *args, **kwargs)
               ^^^^^^^^^^^^^^^^^^^^^^^^^^^^^^^^^
  File "D:\DMS-GOA\DMS_goa\admin_web\views.py", line 1687, in get
    if inc_ws_ve and inc_ws_ve.veh_id:
                     ^^^^^^^^^^^^^^^^
AttributeError: 'QuerySet' object has no attribute 'veh_id'
ERROR 2025-08-25 17:56:47,424 basehttp "GET /admin_web/get_responder_list/10/ HTTP/1.1" 500 99265
ERROR 2025-08-25 17:58:20,150 log Internal Server Error: /admin_web/get_responder_list/10/
Traceback (most recent call last):
  File "D:\DMS-GOA\vvenv\Lib\site-packages\django\core\handlers\exception.py", line 55, in inner
    response = get_response(request)
               ^^^^^^^^^^^^^^^^^^^^^
  File "D:\DMS-GOA\vvenv\Lib\site-packages\django\core\handlers\base.py", line 197, in _get_response
    response = wrapped_callback(request, *callback_args, **callback_kwargs)
               ^^^^^^^^^^^^^^^^^^^^^^^^^^^^^^^^^^^^^^^^^^^^^^^^^^^^^^^^^^^^
  File "D:\DMS-GOA\vvenv\Lib\site-packages\django\views\decorators\csrf.py", line 65, in _view_wrapper
    return view_func(request, *args, **kwargs)
           ^^^^^^^^^^^^^^^^^^^^^^^^^^^^^^^^^^^
  File "D:\DMS-GOA\vvenv\Lib\site-packages\django\views\generic\base.py", line 105, in view
    return self.dispatch(request, *args, **kwargs)
           ^^^^^^^^^^^^^^^^^^^^^^^^^^^^^^^^^^^^^^^
  File "D:\DMS-GOA\vvenv\Lib\site-packages\rest_framework\views.py", line 515, in dispatch
    response = self.handle_exception(exc)
               ^^^^^^^^^^^^^^^^^^^^^^^^^^
  File "D:\DMS-GOA\vvenv\Lib\site-packages\rest_framework\views.py", line 475, in handle_exception
    self.raise_uncaught_exception(exc)
  File "D:\DMS-GOA\vvenv\Lib\site-packages\rest_framework\views.py", line 486, in raise_uncaught_exception
    raise exc
  File "D:\DMS-GOA\vvenv\Lib\site-packages\rest_framework\views.py", line 512, in dispatch
    response = handler(request, *args, **kwargs)
               ^^^^^^^^^^^^^^^^^^^^^^^^^^^^^^^^^
  File "D:\DMS-GOA\DMS_goa\admin_web\views.py", line 1688, in get
    rm_cl_ve = in_cl_dt.filter(vehicle_no__in=inc_ws_ve.veh_id).values_list('vehicle_no', flat=True)
                                              ^^^^^^^^^^^^^^^^
AttributeError: 'QuerySet' object has no attribute 'veh_id'
ERROR 2025-08-25 17:58:20,155 basehttp "GET /admin_web/get_responder_list/10/ HTTP/1.1" 500 99185
ERROR 2025-08-25 17:59:20,748 log Internal Server Error: /admin_web/get_responder_list/10/
Traceback (most recent call last):
  File "D:\DMS-GOA\vvenv\Lib\site-packages\django\core\handlers\exception.py", line 55, in inner
    response = get_response(request)
               ^^^^^^^^^^^^^^^^^^^^^
  File "D:\DMS-GOA\vvenv\Lib\site-packages\django\core\handlers\base.py", line 197, in _get_response
    response = wrapped_callback(request, *callback_args, **callback_kwargs)
               ^^^^^^^^^^^^^^^^^^^^^^^^^^^^^^^^^^^^^^^^^^^^^^^^^^^^^^^^^^^^
  File "D:\DMS-GOA\vvenv\Lib\site-packages\django\views\decorators\csrf.py", line 65, in _view_wrapper
    return view_func(request, *args, **kwargs)
           ^^^^^^^^^^^^^^^^^^^^^^^^^^^^^^^^^^^
  File "D:\DMS-GOA\vvenv\Lib\site-packages\django\views\generic\base.py", line 105, in view
    return self.dispatch(request, *args, **kwargs)
           ^^^^^^^^^^^^^^^^^^^^^^^^^^^^^^^^^^^^^^^
  File "D:\DMS-GOA\vvenv\Lib\site-packages\rest_framework\views.py", line 515, in dispatch
    response = self.handle_exception(exc)
               ^^^^^^^^^^^^^^^^^^^^^^^^^^
  File "D:\DMS-GOA\vvenv\Lib\site-packages\rest_framework\views.py", line 475, in handle_exception
    self.raise_uncaught_exception(exc)
  File "D:\DMS-GOA\vvenv\Lib\site-packages\rest_framework\views.py", line 486, in raise_uncaught_exception
    raise exc
  File "D:\DMS-GOA\vvenv\Lib\site-packages\rest_framework\views.py", line 512, in dispatch
    response = handler(request, *args, **kwargs)
               ^^^^^^^^^^^^^^^^^^^^^^^^^^^^^^^^^
  File "D:\DMS-GOA\DMS_goa\admin_web\views.py", line 1701, in get
    'vehicle_no':iv.veh_id.vehicle_no,
                 ^^^^^^^^^^^^^^^^^^^^
AttributeError: 'Vehical' object has no attribute 'vehicle_no'
ERROR 2025-08-25 17:59:20,755 basehttp "GET /admin_web/get_responder_list/10/ HTTP/1.1" 500 99333
ERROR 2025-08-25 18:17:54,805 log Internal Server Error: /admin_web/get_responder_list/10/
Traceback (most recent call last):
  File "D:\DMS-GOA\vvenv\Lib\site-packages\django\core\handlers\exception.py", line 55, in inner
    response = get_response(request)
               ^^^^^^^^^^^^^^^^^^^^^
  File "D:\DMS-GOA\vvenv\Lib\site-packages\django\core\handlers\base.py", line 197, in _get_response
    response = wrapped_callback(request, *callback_args, **callback_kwargs)
               ^^^^^^^^^^^^^^^^^^^^^^^^^^^^^^^^^^^^^^^^^^^^^^^^^^^^^^^^^^^^
  File "D:\DMS-GOA\vvenv\Lib\site-packages\django\views\decorators\csrf.py", line 65, in _view_wrapper
    return view_func(request, *args, **kwargs)
           ^^^^^^^^^^^^^^^^^^^^^^^^^^^^^^^^^^^
  File "D:\DMS-GOA\vvenv\Lib\site-packages\django\views\generic\base.py", line 105, in view
    return self.dispatch(request, *args, **kwargs)
           ^^^^^^^^^^^^^^^^^^^^^^^^^^^^^^^^^^^^^^^
  File "D:\DMS-GOA\vvenv\Lib\site-packages\rest_framework\views.py", line 515, in dispatch
    response = self.handle_exception(exc)
               ^^^^^^^^^^^^^^^^^^^^^^^^^^
  File "D:\DMS-GOA\vvenv\Lib\site-packages\rest_framework\views.py", line 475, in handle_exception
    self.raise_uncaught_exception(exc)
  File "D:\DMS-GOA\vvenv\Lib\site-packages\rest_framework\views.py", line 486, in raise_uncaught_exception
    raise exc
  File "D:\DMS-GOA\vvenv\Lib\site-packages\rest_framework\views.py", line 512, in dispatch
    response = handler(request, *args, **kwargs)
               ^^^^^^^^^^^^^^^^^^^^^^^^^^^^^^^^^
  File "D:\DMS-GOA\DMS_goa\admin_web\views.py", line 1672, in get
    'vehicle_no': vh.vehicle_no
                  ^^^^^^^^^^^^^
AttributeError: 'Vehical' object has no attribute 'vehicle_no'
ERROR 2025-08-25 18:17:54,815 basehttp "GET /admin_web/get_responder_list/10/ HTTP/1.1" 500 99867
WARNING 2025-08-26 10:23:40,542 log Not Found: /favicon.ico
WARNING 2025-08-26 10:23:40,543 basehttp "GET /favicon.ico HTTP/1.1" 404 2833
WARNING 2025-08-26 10:51:07,438 log Method Not Allowed: /admin_web/get_responder_list/10/
WARNING 2025-08-26 10:51:07,439 basehttp "POST /admin_web/get_responder_list/10/ HTTP/1.1" 405 41
WARNING 2025-08-26 10:52:08,779 log Not Found: /admin_web/closure_post_api/
WARNING 2025-08-26 10:52:08,780 basehttp "POST /admin_web/closure_post_api/ HTTP/1.1" 404 31
WARNING 2025-08-26 10:52:28,914 log Not Found: /admin_web/closure_post_api/
WARNING 2025-08-26 10:52:28,914 basehttp "POST /admin_web/closure_post_api/ HTTP/1.1" 404 31
ERROR 2025-08-26 10:58:21,417 log Internal Server Error: /admin_web/closure_post_api/
ERROR 2025-08-26 10:58:21,418 basehttp "POST /admin_web/closure_post_api/ HTTP/1.1" 500 56
ERROR 2025-08-26 11:01:07,074 log Internal Server Error: /admin_web/closure_post_api/
ERROR 2025-08-26 11:01:07,074 basehttp "POST /admin_web/closure_post_api/ HTTP/1.1" 500 147
WARNING 2025-08-26 15:20:00,696 log Bad Request: /admin_web/closurecomplete/
WARNING 2025-08-26 15:20:00,697 basehttp "POST /admin_web/closurecomplete/ HTTP/1.1" 400 30
WARNING 2025-08-26 15:20:16,163 log Bad Request: /admin_web/closurecomplete/
WARNING 2025-08-26 15:20:16,164 basehttp "POST /admin_web/closurecomplete/ HTTP/1.1" 400 30
WARNING 2025-08-26 15:22:17,310 log Bad Request: /admin_web/closurecomplete/
WARNING 2025-08-26 15:22:17,311 basehttp "POST /admin_web/closurecomplete/ HTTP/1.1" 400 30
WARNING 2025-08-26 15:22:33,901 log Bad Request: /admin_web/closurecomplete/
WARNING 2025-08-26 15:22:33,901 basehttp "POST /admin_web/closurecomplete/ HTTP/1.1" 400 30
WARNING 2025-08-26 15:22:45,307 log Bad Request: /admin_web/closurecomplete/
WARNING 2025-08-26 15:22:45,307 basehttp "POST /admin_web/closurecomplete/ HTTP/1.1" 400 30
ERROR 2025-08-26 15:23:27,168 log Internal Server Error: /admin_web/closurecomplete/
ERROR 2025-08-26 15:23:27,168 basehttp "POST /admin_web/closurecomplete/ HTTP/1.1" 500 79
ERROR 2025-08-26 15:24:22,975 log Internal Server Error: /admin_web/closurecomplete/
ERROR 2025-08-26 15:24:22,975 basehttp "POST /admin_web/closurecomplete/ HTTP/1.1" 500 55
ERROR 2025-08-26 15:24:38,511 log Internal Server Error: /admin_web/closurecomplete/
ERROR 2025-08-26 15:24:38,512 basehttp "POST /admin_web/closurecomplete/ HTTP/1.1" 500 55
ERROR 2025-08-26 15:29:39,747 log Internal Server Error: /admin_web/closurecomplete/
ERROR 2025-08-26 15:29:39,748 basehttp "POST /admin_web/closurecomplete/ HTTP/1.1" 500 63
ERROR 2025-08-26 15:31:03,703 log Internal Server Error: /admin_web/closurecomplete/
ERROR 2025-08-26 15:31:03,704 basehttp "POST /admin_web/closurecomplete/ HTTP/1.1" 500 50
ERROR 2025-08-26 15:31:43,810 log Internal Server Error: /admin_web/closurecomplete/
ERROR 2025-08-26 15:31:43,811 basehttp "POST /admin_web/closurecomplete/ HTTP/1.1" 500 50
ERROR 2025-08-26 15:32:05,598 log Internal Server Error: /admin_web/closurecomplete/
ERROR 2025-08-26 15:32:05,599 basehttp "POST /admin_web/closurecomplete/ HTTP/1.1" 500 63
ERROR 2025-08-26 15:33:37,672 log Internal Server Error: /admin_web/closurecomplete/
ERROR 2025-08-26 15:33:37,673 basehttp "POST /admin_web/closurecomplete/ HTTP/1.1" 500 63
ERROR 2025-08-26 15:33:47,768 log Internal Server Error: /admin_web/closurecomplete/
ERROR 2025-08-26 15:33:47,769 basehttp "POST /admin_web/closurecomplete/ HTTP/1.1" 500 63
ERROR 2025-08-26 15:34:06,116 log Internal Server Error: /admin_web/closurecomplete/
ERROR 2025-08-26 15:34:06,116 basehttp "POST /admin_web/closurecomplete/ HTTP/1.1" 500 63
ERROR 2025-08-26 15:35:24,642 log Internal Server Error: /admin_web/closurecomplete/
ERROR 2025-08-26 15:35:24,643 basehttp "POST /admin_web/closurecomplete/ HTTP/1.1" 500 63
ERROR 2025-08-29 15:23:08,590 log Internal Server Error: /DMS_mdt/Userlistambvise
Traceback (most recent call last):
  File "D:\DMS-GOA\vvenv\Lib\site-packages\django\core\handlers\exception.py", line 55, in inner
    response = get_response(request)
               ^^^^^^^^^^^^^^^^^^^^^
  File "D:\DMS-GOA\vvenv\Lib\site-packages\django\core\handlers\base.py", line 197, in _get_response
    response = wrapped_callback(request, *callback_args, **callback_kwargs)
               ^^^^^^^^^^^^^^^^^^^^^^^^^^^^^^^^^^^^^^^^^^^^^^^^^^^^^^^^^^^^
  File "D:\DMS-GOA\vvenv\Lib\site-packages\django\views\decorators\csrf.py", line 65, in _view_wrapper
    return view_func(request, *args, **kwargs)
           ^^^^^^^^^^^^^^^^^^^^^^^^^^^^^^^^^^^
  File "D:\DMS-GOA\vvenv\Lib\site-packages\django\views\generic\base.py", line 105, in view
    return self.dispatch(request, *args, **kwargs)
           ^^^^^^^^^^^^^^^^^^^^^^^^^^^^^^^^^^^^^^^
  File "D:\DMS-GOA\vvenv\Lib\site-packages\rest_framework\views.py", line 515, in dispatch
    response = self.handle_exception(exc)
               ^^^^^^^^^^^^^^^^^^^^^^^^^^
  File "D:\DMS-GOA\vvenv\Lib\site-packages\rest_framework\views.py", line 475, in handle_exception
    self.raise_uncaught_exception(exc)
  File "D:\DMS-GOA\vvenv\Lib\site-packages\rest_framework\views.py", line 486, in raise_uncaught_exception
    raise exc
  File "D:\DMS-GOA\vvenv\Lib\site-packages\rest_framework\views.py", line 512, in dispatch
    response = handler(request, *args, **kwargs)
               ^^^^^^^^^^^^^^^^^^^^^^^^^^^^^^^^^
  File "D:\DMS-GOA\DMS_goa\DMS_MDT\views.py", line 746, in post
    vehicl_dtls = Vehical.objects.get(veh_number=vehical_no)
                  ^^^^^^^^^^^^^^^^^^^^^^^^^^^^^^^^^^^^^^^^^^
  File "D:\DMS-GOA\vvenv\Lib\site-packages\django\db\models\manager.py", line 87, in manager_method
    return getattr(self.get_queryset(), name)(*args, **kwargs)
           ^^^^^^^^^^^^^^^^^^^^^^^^^^^^^^^^^^^^^^^^^^^^^^^^^^^
  File "D:\DMS-GOA\vvenv\Lib\site-packages\django\db\models\query.py", line 633, in get
    raise self.model.DoesNotExist(
DMS_MDT.models.Vehical.DoesNotExist: Vehical matching query does not exist.
ERROR 2025-08-29 15:23:08,615 basehttp "POST /DMS_mdt/Userlistambvise HTTP/1.1" 500 103938
ERROR 2025-08-29 15:24:55,189 log Internal Server Error: /DMS_mdt/Userlistambvise
Traceback (most recent call last):
  File "D:\DMS-GOA\vvenv\Lib\site-packages\django\core\handlers\exception.py", line 55, in inner
    response = get_response(request)
               ^^^^^^^^^^^^^^^^^^^^^
  File "D:\DMS-GOA\vvenv\Lib\site-packages\django\core\handlers\base.py", line 197, in _get_response
    response = wrapped_callback(request, *callback_args, **callback_kwargs)
               ^^^^^^^^^^^^^^^^^^^^^^^^^^^^^^^^^^^^^^^^^^^^^^^^^^^^^^^^^^^^
  File "D:\DMS-GOA\vvenv\Lib\site-packages\django\views\decorators\csrf.py", line 65, in _view_wrapper
    return view_func(request, *args, **kwargs)
           ^^^^^^^^^^^^^^^^^^^^^^^^^^^^^^^^^^^
  File "D:\DMS-GOA\vvenv\Lib\site-packages\django\views\generic\base.py", line 105, in view
    return self.dispatch(request, *args, **kwargs)
           ^^^^^^^^^^^^^^^^^^^^^^^^^^^^^^^^^^^^^^^
  File "D:\DMS-GOA\vvenv\Lib\site-packages\rest_framework\views.py", line 515, in dispatch
    response = self.handle_exception(exc)
               ^^^^^^^^^^^^^^^^^^^^^^^^^^
  File "D:\DMS-GOA\vvenv\Lib\site-packages\rest_framework\views.py", line 475, in handle_exception
    self.raise_uncaught_exception(exc)
  File "D:\DMS-GOA\vvenv\Lib\site-packages\rest_framework\views.py", line 486, in raise_uncaught_exception
    raise exc
  File "D:\DMS-GOA\vvenv\Lib\site-packages\rest_framework\views.py", line 512, in dispatch
    response = handler(request, *args, **kwargs)
               ^^^^^^^^^^^^^^^^^^^^^^^^^^^^^^^^^
  File "D:\DMS-GOA\DMS_goa\DMS_MDT\views.py", line 746, in post
    vehicl_dtls = Vehical.objects.get(veh_number=vehical_no)
                  ^^^^^^^^^^^^^^^^^^^^^^^^^^^^^^^^^^^^^^^^^^
  File "D:\DMS-GOA\vvenv\Lib\site-packages\django\db\models\manager.py", line 87, in manager_method
    return getattr(self.get_queryset(), name)(*args, **kwargs)
           ^^^^^^^^^^^^^^^^^^^^^^^^^^^^^^^^^^^^^^^^^^^^^^^^^^^
  File "D:\DMS-GOA\vvenv\Lib\site-packages\django\db\models\query.py", line 633, in get
    raise self.model.DoesNotExist(
DMS_MDT.models.Vehical.DoesNotExist: Vehical matching query does not exist.
ERROR 2025-08-29 15:24:55,205 basehttp "POST /DMS_mdt/Userlistambvise HTTP/1.1" 500 103959
ERROR 2025-08-29 15:26:38,522 log Internal Server Error: /DMS_mdt/Userlistambvise
Traceback (most recent call last):
  File "D:\DMS-GOA\vvenv\Lib\site-packages\django\core\handlers\exception.py", line 55, in inner
    response = get_response(request)
               ^^^^^^^^^^^^^^^^^^^^^
  File "D:\DMS-GOA\vvenv\Lib\site-packages\django\core\handlers\base.py", line 197, in _get_response
    response = wrapped_callback(request, *callback_args, **callback_kwargs)
               ^^^^^^^^^^^^^^^^^^^^^^^^^^^^^^^^^^^^^^^^^^^^^^^^^^^^^^^^^^^^
  File "D:\DMS-GOA\vvenv\Lib\site-packages\django\views\decorators\csrf.py", line 65, in _view_wrapper
    return view_func(request, *args, **kwargs)
           ^^^^^^^^^^^^^^^^^^^^^^^^^^^^^^^^^^^
  File "D:\DMS-GOA\vvenv\Lib\site-packages\django\views\generic\base.py", line 105, in view
    return self.dispatch(request, *args, **kwargs)
           ^^^^^^^^^^^^^^^^^^^^^^^^^^^^^^^^^^^^^^^
  File "D:\DMS-GOA\vvenv\Lib\site-packages\rest_framework\views.py", line 515, in dispatch
    response = self.handle_exception(exc)
               ^^^^^^^^^^^^^^^^^^^^^^^^^^
  File "D:\DMS-GOA\vvenv\Lib\site-packages\rest_framework\views.py", line 475, in handle_exception
    self.raise_uncaught_exception(exc)
  File "D:\DMS-GOA\vvenv\Lib\site-packages\rest_framework\views.py", line 486, in raise_uncaught_exception
    raise exc
  File "D:\DMS-GOA\vvenv\Lib\site-packages\rest_framework\views.py", line 512, in dispatch
    response = handler(request, *args, **kwargs)
               ^^^^^^^^^^^^^^^^^^^^^^^^^^^^^^^^^
  File "D:\DMS-GOA\DMS_goa\DMS_MDT\views.py", line 746, in post
    vehicl_dtls = Vehical.objects.get(veh_number=vehical_no)
                  ^^^^^^^^^^^^^^^^^^^^^^^^^^^^^^^^^^^^^^^^^^
  File "D:\DMS-GOA\vvenv\Lib\site-packages\django\db\models\manager.py", line 87, in manager_method
    return getattr(self.get_queryset(), name)(*args, **kwargs)
           ^^^^^^^^^^^^^^^^^^^^^^^^^^^^^^^^^^^^^^^^^^^^^^^^^^^
  File "D:\DMS-GOA\vvenv\Lib\site-packages\django\db\models\query.py", line 633, in get
    raise self.model.DoesNotExist(
DMS_MDT.models.Vehical.DoesNotExist: Vehical matching query does not exist.
ERROR 2025-08-29 15:26:38,528 basehttp "POST /DMS_mdt/Userlistambvise HTTP/1.1" 500 103959
ERROR 2025-08-29 15:27:23,853 log Internal Server Error: /DMS_mdt/Userlistambvise
Traceback (most recent call last):
  File "D:\DMS-GOA\vvenv\Lib\site-packages\django\core\handlers\exception.py", line 55, in inner
    response = get_response(request)
               ^^^^^^^^^^^^^^^^^^^^^
  File "D:\DMS-GOA\vvenv\Lib\site-packages\django\core\handlers\base.py", line 197, in _get_response
    response = wrapped_callback(request, *callback_args, **callback_kwargs)
               ^^^^^^^^^^^^^^^^^^^^^^^^^^^^^^^^^^^^^^^^^^^^^^^^^^^^^^^^^^^^
  File "D:\DMS-GOA\vvenv\Lib\site-packages\django\views\decorators\csrf.py", line 65, in _view_wrapper
    return view_func(request, *args, **kwargs)
           ^^^^^^^^^^^^^^^^^^^^^^^^^^^^^^^^^^^
  File "D:\DMS-GOA\vvenv\Lib\site-packages\django\views\generic\base.py", line 105, in view
    return self.dispatch(request, *args, **kwargs)
           ^^^^^^^^^^^^^^^^^^^^^^^^^^^^^^^^^^^^^^^
  File "D:\DMS-GOA\vvenv\Lib\site-packages\rest_framework\views.py", line 515, in dispatch
    response = self.handle_exception(exc)
               ^^^^^^^^^^^^^^^^^^^^^^^^^^
  File "D:\DMS-GOA\vvenv\Lib\site-packages\rest_framework\views.py", line 475, in handle_exception
    self.raise_uncaught_exception(exc)
  File "D:\DMS-GOA\vvenv\Lib\site-packages\rest_framework\views.py", line 486, in raise_uncaught_exception
    raise exc
  File "D:\DMS-GOA\vvenv\Lib\site-packages\rest_framework\views.py", line 512, in dispatch
    response = handler(request, *args, **kwargs)
               ^^^^^^^^^^^^^^^^^^^^^^^^^^^^^^^^^
  File "D:\DMS-GOA\DMS_goa\DMS_MDT\views.py", line 747, in post
    vehicl_dtls = Vehical.objects.get(veh_number=vehical_no)
                  ^^^^^^^^^^^^^^^^^^^^^^^^^^^^^^^^^^^^^^^^^^
  File "D:\DMS-GOA\vvenv\Lib\site-packages\django\db\models\manager.py", line 87, in manager_method
    return getattr(self.get_queryset(), name)(*args, **kwargs)
           ^^^^^^^^^^^^^^^^^^^^^^^^^^^^^^^^^^^^^^^^^^^^^^^^^^^
  File "D:\DMS-GOA\vvenv\Lib\site-packages\django\db\models\query.py", line 633, in get
    raise self.model.DoesNotExist(
DMS_MDT.models.Vehical.DoesNotExist: Vehical matching query does not exist.
ERROR 2025-08-29 15:27:23,865 basehttp "POST /DMS_mdt/Userlistambvise HTTP/1.1" 500 103984
ERROR 2025-08-29 15:28:04,309 log Internal Server Error: /DMS_mdt/Userlistambvise
Traceback (most recent call last):
  File "D:\DMS-GOA\vvenv\Lib\site-packages\django\core\handlers\exception.py", line 55, in inner
    response = get_response(request)
               ^^^^^^^^^^^^^^^^^^^^^
  File "D:\DMS-GOA\vvenv\Lib\site-packages\django\core\handlers\base.py", line 197, in _get_response
    response = wrapped_callback(request, *callback_args, **callback_kwargs)
               ^^^^^^^^^^^^^^^^^^^^^^^^^^^^^^^^^^^^^^^^^^^^^^^^^^^^^^^^^^^^
  File "D:\DMS-GOA\vvenv\Lib\site-packages\django\views\decorators\csrf.py", line 65, in _view_wrapper
    return view_func(request, *args, **kwargs)
           ^^^^^^^^^^^^^^^^^^^^^^^^^^^^^^^^^^^
  File "D:\DMS-GOA\vvenv\Lib\site-packages\django\views\generic\base.py", line 105, in view
    return self.dispatch(request, *args, **kwargs)
           ^^^^^^^^^^^^^^^^^^^^^^^^^^^^^^^^^^^^^^^
  File "D:\DMS-GOA\vvenv\Lib\site-packages\rest_framework\views.py", line 515, in dispatch
    response = self.handle_exception(exc)
               ^^^^^^^^^^^^^^^^^^^^^^^^^^
  File "D:\DMS-GOA\vvenv\Lib\site-packages\rest_framework\views.py", line 475, in handle_exception
    self.raise_uncaught_exception(exc)
  File "D:\DMS-GOA\vvenv\Lib\site-packages\rest_framework\views.py", line 486, in raise_uncaught_exception
    raise exc
  File "D:\DMS-GOA\vvenv\Lib\site-packages\rest_framework\views.py", line 512, in dispatch
    response = handler(request, *args, **kwargs)
               ^^^^^^^^^^^^^^^^^^^^^^^^^^^^^^^^^
  File "D:\DMS-GOA\DMS_goa\DMS_MDT\views.py", line 747, in post
    vehicl_dtls = Vehical.objects.get(veh_number=vehical_no)
                  ^^^^^^^^^^^^^^^^^^^^^^^^^^^^^^^^^^^^^^^^^^
  File "D:\DMS-GOA\vvenv\Lib\site-packages\django\db\models\manager.py", line 87, in manager_method
    return getattr(self.get_queryset(), name)(*args, **kwargs)
           ^^^^^^^^^^^^^^^^^^^^^^^^^^^^^^^^^^^^^^^^^^^^^^^^^^^
  File "D:\DMS-GOA\vvenv\Lib\site-packages\django\db\models\query.py", line 633, in get
    raise self.model.DoesNotExist(
DMS_MDT.models.Vehical.DoesNotExist: Vehical matching query does not exist.
ERROR 2025-08-29 15:28:04,379 basehttp "POST /DMS_mdt/Userlistambvise HTTP/1.1" 500 103939
ERROR 2025-08-29 15:28:15,210 log Internal Server Error: /DMS_mdt/Userlistambvise
Traceback (most recent call last):
  File "D:\DMS-GOA\vvenv\Lib\site-packages\django\core\handlers\exception.py", line 55, in inner
    response = get_response(request)
               ^^^^^^^^^^^^^^^^^^^^^
  File "D:\DMS-GOA\vvenv\Lib\site-packages\django\core\handlers\base.py", line 197, in _get_response
    response = wrapped_callback(request, *callback_args, **callback_kwargs)
               ^^^^^^^^^^^^^^^^^^^^^^^^^^^^^^^^^^^^^^^^^^^^^^^^^^^^^^^^^^^^
  File "D:\DMS-GOA\vvenv\Lib\site-packages\django\views\decorators\csrf.py", line 65, in _view_wrapper
    return view_func(request, *args, **kwargs)
           ^^^^^^^^^^^^^^^^^^^^^^^^^^^^^^^^^^^
  File "D:\DMS-GOA\vvenv\Lib\site-packages\django\views\generic\base.py", line 105, in view
    return self.dispatch(request, *args, **kwargs)
           ^^^^^^^^^^^^^^^^^^^^^^^^^^^^^^^^^^^^^^^
  File "D:\DMS-GOA\vvenv\Lib\site-packages\rest_framework\views.py", line 515, in dispatch
    response = self.handle_exception(exc)
               ^^^^^^^^^^^^^^^^^^^^^^^^^^
  File "D:\DMS-GOA\vvenv\Lib\site-packages\rest_framework\views.py", line 475, in handle_exception
    self.raise_uncaught_exception(exc)
  File "D:\DMS-GOA\vvenv\Lib\site-packages\rest_framework\views.py", line 486, in raise_uncaught_exception
    raise exc
  File "D:\DMS-GOA\vvenv\Lib\site-packages\rest_framework\views.py", line 512, in dispatch
    response = handler(request, *args, **kwargs)
               ^^^^^^^^^^^^^^^^^^^^^^^^^^^^^^^^^
  File "D:\DMS-GOA\DMS_goa\DMS_MDT\views.py", line 747, in post
    vehicl_dtls = Vehical.objects.get(veh_number=vehical_no)
                  ^^^^^^^^^^^^^^^^^^^^^^^^^^^^^^^^^^^^^^^^^^
  File "D:\DMS-GOA\vvenv\Lib\site-packages\django\db\models\manager.py", line 87, in manager_method
    return getattr(self.get_queryset(), name)(*args, **kwargs)
           ^^^^^^^^^^^^^^^^^^^^^^^^^^^^^^^^^^^^^^^^^^^^^^^^^^^
  File "D:\DMS-GOA\vvenv\Lib\site-packages\django\db\models\query.py", line 633, in get
    raise self.model.DoesNotExist(
DMS_MDT.models.Vehical.DoesNotExist: Vehical matching query does not exist.
ERROR 2025-08-29 15:28:15,210 basehttp "POST /DMS_mdt/Userlistambvise HTTP/1.1" 500 103939
ERROR 2025-08-29 18:09:19,228 log Internal Server Error: /DMS_mdt/compincidentinfo
Traceback (most recent call last):
  File "D:\DMS-GOA\vvenv\Lib\site-packages\django\core\handlers\exception.py", line 55, in inner
    response = get_response(request)
               ^^^^^^^^^^^^^^^^^^^^^
  File "D:\DMS-GOA\vvenv\Lib\site-packages\django\core\handlers\base.py", line 197, in _get_response
    response = wrapped_callback(request, *callback_args, **callback_kwargs)
               ^^^^^^^^^^^^^^^^^^^^^^^^^^^^^^^^^^^^^^^^^^^^^^^^^^^^^^^^^^^^
  File "D:\DMS-GOA\vvenv\Lib\site-packages\django\views\decorators\csrf.py", line 65, in _view_wrapper
    return view_func(request, *args, **kwargs)
           ^^^^^^^^^^^^^^^^^^^^^^^^^^^^^^^^^^^
  File "D:\DMS-GOA\vvenv\Lib\site-packages\django\views\generic\base.py", line 105, in view
    return self.dispatch(request, *args, **kwargs)
           ^^^^^^^^^^^^^^^^^^^^^^^^^^^^^^^^^^^^^^^
  File "D:\DMS-GOA\vvenv\Lib\site-packages\rest_framework\views.py", line 515, in dispatch
    response = self.handle_exception(exc)
               ^^^^^^^^^^^^^^^^^^^^^^^^^^
  File "D:\DMS-GOA\vvenv\Lib\site-packages\rest_framework\views.py", line 475, in handle_exception
    self.raise_uncaught_exception(exc)
  File "D:\DMS-GOA\vvenv\Lib\site-packages\rest_framework\views.py", line 486, in raise_uncaught_exception
    raise exc
  File "D:\DMS-GOA\vvenv\Lib\site-packages\rest_framework\views.py", line 512, in dispatch
    response = handler(request, *args, **kwargs)
               ^^^^^^^^^^^^^^^^^^^^^^^^^^^^^^^^^
  File "D:\DMS-GOA\DMS_goa\DMS_MDT\views.py", line 599, in post
    incidentDate = incident_datetime.datetime.strftime("%Y-%m-%d")   # e.g. "2025-08-25"
                   ^^^^^^^^^^^^^^^^^^^^^^^^^^
AttributeError: 'datetime.datetime' object has no attribute 'datetime'
ERROR 2025-08-29 18:09:19,239 basehttp "POST /DMS_mdt/compincidentinfo HTTP/1.1" 500 97056
WARNING 2025-09-01 16:45:18,827 log Not Found: /DMS_mdt/closurecomplete/
WARNING 2025-09-01 16:45:18,829 basehttp "POST /DMS_mdt/closurecomplete/ HTTP/1.1" 404 7449
WARNING 2025-09-01 16:45:34,741 log Not Found: /DMS_mdt/closurecomplete/
WARNING 2025-09-01 16:45:34,743 basehttp "POST /DMS_mdt/closurecomplete/ HTTP/1.1" 404 7449
ERROR 2025-09-01 18:09:35,112 log Internal Server Error: /admin_web/get_responder_list/81/
Traceback (most recent call last):
  File "D:\DMS-GOA\vvenv\Lib\site-packages\django\core\handlers\exception.py", line 55, in inner
    response = get_response(request)
               ^^^^^^^^^^^^^^^^^^^^^
  File "D:\DMS-GOA\vvenv\Lib\site-packages\django\core\handlers\base.py", line 197, in _get_response
    response = wrapped_callback(request, *callback_args, **callback_kwargs)
               ^^^^^^^^^^^^^^^^^^^^^^^^^^^^^^^^^^^^^^^^^^^^^^^^^^^^^^^^^^^^
  File "D:\DMS-GOA\vvenv\Lib\site-packages\django\views\decorators\csrf.py", line 65, in _view_wrapper
    return view_func(request, *args, **kwargs)
           ^^^^^^^^^^^^^^^^^^^^^^^^^^^^^^^^^^^
  File "D:\DMS-GOA\vvenv\Lib\site-packages\django\views\generic\base.py", line 105, in view
    return self.dispatch(request, *args, **kwargs)
           ^^^^^^^^^^^^^^^^^^^^^^^^^^^^^^^^^^^^^^^
  File "D:\DMS-GOA\vvenv\Lib\site-packages\rest_framework\views.py", line 515, in dispatch
    response = self.handle_exception(exc)
               ^^^^^^^^^^^^^^^^^^^^^^^^^^
  File "D:\DMS-GOA\vvenv\Lib\site-packages\rest_framework\views.py", line 475, in handle_exception
    self.raise_uncaught_exception(exc)
  File "D:\DMS-GOA\vvenv\Lib\site-packages\rest_framework\views.py", line 486, in raise_uncaught_exception
    raise exc
  File "D:\DMS-GOA\vvenv\Lib\site-packages\rest_framework\views.py", line 512, in dispatch
    response = handler(request, *args, **kwargs)
               ^^^^^^^^^^^^^^^^^^^^^^^^^^^^^^^^^
  File "D:\DMS-GOA\DMS_goa\admin_web\views.py", line 1751, in get
    responder_id = i.veh_id.responder.responder_id
                   ^^^^^^^^^^^^^^^^^^^^^^^^^^^^^^^
AttributeError: 'NoneType' object has no attribute 'responder_id'
ERROR 2025-09-01 18:09:35,121 basehttp "GET /admin_web/get_responder_list/81/ HTTP/1.1" 500 96768
ERROR 2025-09-01 18:10:21,470 log Internal Server Error: /admin_web/get_responder_list/81/
Traceback (most recent call last):
  File "D:\DMS-GOA\vvenv\Lib\site-packages\django\core\handlers\exception.py", line 55, in inner
    response = get_response(request)
               ^^^^^^^^^^^^^^^^^^^^^
  File "D:\DMS-GOA\vvenv\Lib\site-packages\django\core\handlers\base.py", line 197, in _get_response
    response = wrapped_callback(request, *callback_args, **callback_kwargs)
               ^^^^^^^^^^^^^^^^^^^^^^^^^^^^^^^^^^^^^^^^^^^^^^^^^^^^^^^^^^^^
  File "D:\DMS-GOA\vvenv\Lib\site-packages\django\views\decorators\csrf.py", line 65, in _view_wrapper
    return view_func(request, *args, **kwargs)
           ^^^^^^^^^^^^^^^^^^^^^^^^^^^^^^^^^^^
  File "D:\DMS-GOA\vvenv\Lib\site-packages\django\views\generic\base.py", line 105, in view
    return self.dispatch(request, *args, **kwargs)
           ^^^^^^^^^^^^^^^^^^^^^^^^^^^^^^^^^^^^^^^
  File "D:\DMS-GOA\vvenv\Lib\site-packages\rest_framework\views.py", line 515, in dispatch
    response = self.handle_exception(exc)
               ^^^^^^^^^^^^^^^^^^^^^^^^^^
  File "D:\DMS-GOA\vvenv\Lib\site-packages\rest_framework\views.py", line 475, in handle_exception
    self.raise_uncaught_exception(exc)
  File "D:\DMS-GOA\vvenv\Lib\site-packages\rest_framework\views.py", line 486, in raise_uncaught_exception
    raise exc
  File "D:\DMS-GOA\vvenv\Lib\site-packages\rest_framework\views.py", line 512, in dispatch
    response = handler(request, *args, **kwargs)
               ^^^^^^^^^^^^^^^^^^^^^^^^^^^^^^^^^
  File "D:\DMS-GOA\DMS_goa\admin_web\views.py", line 1752, in get
    responder_id = i.veh_id.responder.responder_id
                   ^^^^^^^^^^^^^^^^^^^^^^^^^^^^^^^
AttributeError: 'NoneType' object has no attribute 'responder_id'
ERROR 2025-09-01 18:10:21,483 basehttp "GET /admin_web/get_responder_list/81/ HTTP/1.1" 500 96731
ERROR 2025-09-02 12:01:51,312 log Internal Server Error: /admin_web/get_responder_list/100/
Traceback (most recent call last):
  File "D:\DMS-GOA\vvenv\Lib\site-packages\django\core\handlers\exception.py", line 55, in inner
    response = get_response(request)
               ^^^^^^^^^^^^^^^^^^^^^
  File "D:\DMS-GOA\vvenv\Lib\site-packages\django\core\handlers\base.py", line 197, in _get_response
    response = wrapped_callback(request, *callback_args, **callback_kwargs)
               ^^^^^^^^^^^^^^^^^^^^^^^^^^^^^^^^^^^^^^^^^^^^^^^^^^^^^^^^^^^^
  File "D:\DMS-GOA\vvenv\Lib\site-packages\django\views\decorators\csrf.py", line 65, in _view_wrapper
    return view_func(request, *args, **kwargs)
           ^^^^^^^^^^^^^^^^^^^^^^^^^^^^^^^^^^^
  File "D:\DMS-GOA\vvenv\Lib\site-packages\django\views\generic\base.py", line 105, in view
    return self.dispatch(request, *args, **kwargs)
           ^^^^^^^^^^^^^^^^^^^^^^^^^^^^^^^^^^^^^^^
  File "D:\DMS-GOA\vvenv\Lib\site-packages\rest_framework\views.py", line 515, in dispatch
    response = self.handle_exception(exc)
               ^^^^^^^^^^^^^^^^^^^^^^^^^^
  File "D:\DMS-GOA\vvenv\Lib\site-packages\rest_framework\views.py", line 475, in handle_exception
    self.raise_uncaught_exception(exc)
  File "D:\DMS-GOA\vvenv\Lib\site-packages\rest_framework\views.py", line 486, in raise_uncaught_exception
    raise exc
  File "D:\DMS-GOA\vvenv\Lib\site-packages\rest_framework\views.py", line 512, in dispatch
    response = handler(request, *args, **kwargs)
               ^^^^^^^^^^^^^^^^^^^^^^^^^^^^^^^^^
  File "D:\DMS-GOA\DMS_goa\admin_web\views.py", line 1724, in get
    inc_dtl = DMS_Incident.objects.get(incident_id=inc_id)
              ^^^^^^^^^^^^^^^^^^^^^^^^^^^^^^^^^^^^^^^^^^^^
  File "D:\DMS-GOA\vvenv\Lib\site-packages\django\db\models\manager.py", line 87, in manager_method
    return getattr(self.get_queryset(), name)(*args, **kwargs)
           ^^^^^^^^^^^^^^^^^^^^^^^^^^^^^^^^^^^^^^^^^^^^^^^^^^^
  File "D:\DMS-GOA\vvenv\Lib\site-packages\django\db\models\query.py", line 633, in get
    raise self.model.DoesNotExist(
admin_web.models.DMS_Incident.DoesNotExist: DMS_Incident matching query does not exist.
ERROR 2025-09-02 12:01:51,318 basehttp "GET /admin_web/get_responder_list/100/ HTTP/1.1" 500 107208
ERROR 2025-09-02 12:02:17,213 log Internal Server Error: /admin_web/get_responder_list/100/
Traceback (most recent call last):
  File "D:\DMS-GOA\vvenv\Lib\site-packages\django\core\handlers\exception.py", line 55, in inner
    response = get_response(request)
               ^^^^^^^^^^^^^^^^^^^^^
  File "D:\DMS-GOA\vvenv\Lib\site-packages\django\core\handlers\base.py", line 197, in _get_response
    response = wrapped_callback(request, *callback_args, **callback_kwargs)
               ^^^^^^^^^^^^^^^^^^^^^^^^^^^^^^^^^^^^^^^^^^^^^^^^^^^^^^^^^^^^
  File "D:\DMS-GOA\vvenv\Lib\site-packages\django\views\decorators\csrf.py", line 65, in _view_wrapper
    return view_func(request, *args, **kwargs)
           ^^^^^^^^^^^^^^^^^^^^^^^^^^^^^^^^^^^
  File "D:\DMS-GOA\vvenv\Lib\site-packages\django\views\generic\base.py", line 105, in view
    return self.dispatch(request, *args, **kwargs)
           ^^^^^^^^^^^^^^^^^^^^^^^^^^^^^^^^^^^^^^^
  File "D:\DMS-GOA\vvenv\Lib\site-packages\rest_framework\views.py", line 515, in dispatch
    response = self.handle_exception(exc)
               ^^^^^^^^^^^^^^^^^^^^^^^^^^
  File "D:\DMS-GOA\vvenv\Lib\site-packages\rest_framework\views.py", line 475, in handle_exception
    self.raise_uncaught_exception(exc)
  File "D:\DMS-GOA\vvenv\Lib\site-packages\rest_framework\views.py", line 486, in raise_uncaught_exception
    raise exc
  File "D:\DMS-GOA\vvenv\Lib\site-packages\rest_framework\views.py", line 512, in dispatch
    response = handler(request, *args, **kwargs)
               ^^^^^^^^^^^^^^^^^^^^^^^^^^^^^^^^^
  File "D:\DMS-GOA\DMS_goa\admin_web\views.py", line 1726, in get
    for i in inc_dtl.responder_scope:
             ^^^^^^^^^^^^^^^^^^^^^^^
TypeError: 'ManyRelatedManager' object is not iterable
ERROR 2025-09-02 12:02:17,215 basehttp "GET /admin_web/get_responder_list/100/ HTTP/1.1" 500 97984
ERROR 2025-09-02 12:02:19,342 log Internal Server Error: /admin_web/get_responder_list/100/
Traceback (most recent call last):
  File "D:\DMS-GOA\vvenv\Lib\site-packages\django\core\handlers\exception.py", line 55, in inner
    response = get_response(request)
               ^^^^^^^^^^^^^^^^^^^^^
  File "D:\DMS-GOA\vvenv\Lib\site-packages\django\core\handlers\base.py", line 197, in _get_response
    response = wrapped_callback(request, *callback_args, **callback_kwargs)
               ^^^^^^^^^^^^^^^^^^^^^^^^^^^^^^^^^^^^^^^^^^^^^^^^^^^^^^^^^^^^
  File "D:\DMS-GOA\vvenv\Lib\site-packages\django\views\decorators\csrf.py", line 65, in _view_wrapper
    return view_func(request, *args, **kwargs)
           ^^^^^^^^^^^^^^^^^^^^^^^^^^^^^^^^^^^
  File "D:\DMS-GOA\vvenv\Lib\site-packages\django\views\generic\base.py", line 105, in view
    return self.dispatch(request, *args, **kwargs)
           ^^^^^^^^^^^^^^^^^^^^^^^^^^^^^^^^^^^^^^^
  File "D:\DMS-GOA\vvenv\Lib\site-packages\rest_framework\views.py", line 515, in dispatch
    response = self.handle_exception(exc)
               ^^^^^^^^^^^^^^^^^^^^^^^^^^
  File "D:\DMS-GOA\vvenv\Lib\site-packages\rest_framework\views.py", line 475, in handle_exception
    self.raise_uncaught_exception(exc)
  File "D:\DMS-GOA\vvenv\Lib\site-packages\rest_framework\views.py", line 486, in raise_uncaught_exception
    raise exc
  File "D:\DMS-GOA\vvenv\Lib\site-packages\rest_framework\views.py", line 512, in dispatch
    response = handler(request, *args, **kwargs)
               ^^^^^^^^^^^^^^^^^^^^^^^^^^^^^^^^^
  File "D:\DMS-GOA\DMS_goa\admin_web\views.py", line 1726, in get
    for i in inc_dtl.responder_scope:
             ^^^^^^^^^^^^^^^^^^^^^^^
TypeError: 'ManyRelatedManager' object is not iterable
ERROR 2025-09-02 12:02:19,344 basehttp "GET /admin_web/get_responder_list/100/ HTTP/1.1" 500 97984
ERROR 2025-09-02 12:02:54,672 log Internal Server Error: /admin_web/get_responder_list/100/
Traceback (most recent call last):
  File "D:\DMS-GOA\vvenv\Lib\site-packages\django\core\handlers\exception.py", line 55, in inner
    response = get_response(request)
               ^^^^^^^^^^^^^^^^^^^^^
  File "D:\DMS-GOA\vvenv\Lib\site-packages\django\core\handlers\base.py", line 197, in _get_response
    response = wrapped_callback(request, *callback_args, **callback_kwargs)
               ^^^^^^^^^^^^^^^^^^^^^^^^^^^^^^^^^^^^^^^^^^^^^^^^^^^^^^^^^^^^
  File "D:\DMS-GOA\vvenv\Lib\site-packages\django\views\decorators\csrf.py", line 65, in _view_wrapper
    return view_func(request, *args, **kwargs)
           ^^^^^^^^^^^^^^^^^^^^^^^^^^^^^^^^^^^
  File "D:\DMS-GOA\vvenv\Lib\site-packages\django\views\generic\base.py", line 105, in view
    return self.dispatch(request, *args, **kwargs)
           ^^^^^^^^^^^^^^^^^^^^^^^^^^^^^^^^^^^^^^^
  File "D:\DMS-GOA\vvenv\Lib\site-packages\rest_framework\views.py", line 515, in dispatch
    response = self.handle_exception(exc)
               ^^^^^^^^^^^^^^^^^^^^^^^^^^
  File "D:\DMS-GOA\vvenv\Lib\site-packages\rest_framework\views.py", line 475, in handle_exception
    self.raise_uncaught_exception(exc)
  File "D:\DMS-GOA\vvenv\Lib\site-packages\rest_framework\views.py", line 486, in raise_uncaught_exception
    raise exc
  File "D:\DMS-GOA\vvenv\Lib\site-packages\rest_framework\views.py", line 512, in dispatch
    response = handler(request, *args, **kwargs)
               ^^^^^^^^^^^^^^^^^^^^^^^^^^^^^^^^^
  File "D:\DMS-GOA\DMS_goa\admin_web\views.py", line 1726, in get
    for i in inc_dtl.responder_scope:
             ^^^^^^^^^^^^^^^^^^^^^^^
TypeError: 'ManyRelatedManager' object is not iterable
ERROR 2025-09-02 12:02:54,674 basehttp "GET /admin_web/get_responder_list/100/ HTTP/1.1" 500 97984
